Workbook

Sheet Uncovered Branches
A1: NIB International Bank S.C
A2: Internal Control Division
A3: Lists of Branches that failed to cover in the monthly internal Control Reports
A4: As of july,2026
A5: Ser. No | B5: Name of Branches | C5: Name of Districts | D5: Reasons for failing to uncover in the monthly internal Control Reports
D7: Operation area
A8: 1 | B8: 22 Megenagna | C8: East | D8: resign
A9: 2 | B9: Sheger menefesha | C9: North | D9: maturnity leave
A10: 3 | B10: Habte giorgis | C10: North | D10: maturnity leave
A11: 4 | B11: Salo Gora | C11: South | D11: Sick Leave
A12: 5 | B12: Asko | C12: West | D12: Sick Leave
A13: 6 | B13: Moyale | C13: Hawassa | D13: Controllers not assigned
A14: 7 | B14: Adare | C14: Hawassa | D14: maturnity leave
A15: 8 | B15: Alamura | C15: Hawassa | D15: maturnity leave
A16: 9 | B16: Tabor | C16: Hawassa | D16: maturnity leave
A17: 10 | B17: Nib Halal | C17: Hawassa | D17: Controllers has not given access right
A18: 11 | B18: Metema | C18: B-Dar | D18: Sick Leave
A19: 12 | B19: Agarfa | C19: Adama | D19: Controllers not assigned
... A57: 50 | B57: Bako | C57: Jimma | D57: Controller not Assigned

Sheet Case Summarised
A1: Monthly Controllers report as at July 2026
A2: SN | B2: Total No. of Branches | C2: District | D2: ATM Cases | H2: IT Case | J2: No. of zero balance account | L2: No. of inactive balance account | N2: Cheque Book case | P2: Others Case | R2: Status of the irregularities
D3: Mismatch | F3: Long outstanding | R3: Total Reported Case | S3: Rectified | T3: Outstanding Case | U3: rectified percetage
B4: A | C4: B | D4: ReportedCase | E4: Rectified | F4: Reported Case | G4: Rectified | H4: Reported Case | I4: Rectified | J4: Reported Case | K4: Rectified | L4: Reported Case | M4: Rectified | N4: Reported Case | O4: Rectified | P4: Reported Case | Q4: Rectified | R4: F | S4: G
A5: 1 | B5: 49 | C5: East | D5: =East!E763 -> 0 | E5: =East!O766 -> 0 | F5: =East!F760 -> 25057 | G5: =East!O767 -> 6 | H5: =East!G760 -> 135 | I5: =East!O768 -> 4 | J5: =East!H760 -> 3973 | K5: =East!O768 -> 4 | L5: =East!I760 -> 87889 | M5: =East!O770 -> 90 | N5: =East!J760 -> 49 | O5: =East!O771 -> 0 | P5: =East!K760 -> 625 | Q5: =East!O772 -> 241 | R5: =D5+F5+H5+J5+L5+N5+P5 -> 117728 | S5: =E5+G5+K5+I5+M5+O5+Q5 -> 345 | T5: =R5-S5 -> 117383
A6: 2 | B6: 42 | C6: North | D6: =North!G377 -> 5283 | E6: =North!K382 -> 90 | F6: =North!H377 -> 16438 | G6: =North!K383 -> 38 | H6: =North!I377 -> 129 | I6: =North!K384 -> 1 | J6: =North!J377 -> 6798 | K6: =North!K385 -> 143 | L6: =North!K377 -> 27137 | M6: =North!K386 -> 58 | N6: =North!L377 -> 990 | O6: =North!K387 -> 0 | P6: =North!M377 -> 228 | Q6: =North!K388 -> 65 | R6: =D6+F6+H6+J6+L6+N6+P6 -> 57003 | S6: =E6+G6+K6+I6+M6+O6+Q6 -> 395 | T6: =R6-S6 -> 56608 | U6: =S6/R6 -> 0.0069294599
A7: 3 | B7: 57 | C7: South | D7: =South!E1066 -> 8018 | E7: =South!O1072 -> 0 | F7: =South!F1066 -> 27504 | G7: =South!O1073 -> 0 | H7: =South!G1066 -> 312 | I7: =South!O1074 -> 0 | J7: =South!H1066 -> 9969 | K7: =South!O1075 -> 0 | L7: =South!I1066 -> 158159 | M7: =South!O1076 -> 0 | N7: =South!J1066 -> 971 | O7: =South!O1077 -> 0 | P7: =South!K1066 -> 818 | Q7: =South!O1078 -> 8 | R7: =D7+F7+H7+J7+L7+N7+P7 -> 205751 | S7: =E7+G7+K7+I7+M7+O7+Q7 -> 8 | T7: =R7-S7 -> 205743 | U7: =S7/R7 -> 3.888195e-05
A8: 4 | B8: 65 | C8: West | D8: =West!E514 -> 5776 | E8: =West!F524 -> 0 | F8: =West!F514 -> 19909 | G8: =West!F525 -> 0 | H8: =West!G514 -> 193 | I8: =West!F526 -> 0 | J8: =West!H514 -> 864 | K8: =West!F527 -> 0 | L8: =West!I514 -> 91240 | M8: =West!F528 -> 0 | N8: =West!J514 -> 2773 | O8: =West!F528 -> 0 | P8: =West!K514 -> 160 | Q8: =West!F530 -> 20 | R8: =D8+F8+H8+J8+L8+N8+P8 -> 120915 | S8: =E8+G8+K8+I8+M8+O8+Q8 -> 20 | T8: =R8-S8 -> 120895 | U8: =S8/R8 -> 0.00016540545
A9: 5 | B9: 33 | C9: Adama | D9: =Adama!E282 -> 1232 | E9: =Adama!F292 -> 20 | F9: =Adama!F282 -> 16571 | G9: =Adama!F293 -> 5 | H9: =Adama!G282 -> 73 | I9: =Adama!F294 -> 22 | J9: =Adama!H282 -> 274 | K9: =Adama!F295 -> 10 | L9: =Adama!I282 -> 94745 | M9: =Adama!F296 -> 0 | N9: =Adama!J282 -> 0 | O9: =Adama!F297 -> 0 | P9: =Adama!K282 -> 207 | Q9: =Adama!F298 -> 20 | R9: =D9+F9+H9+J9+L9+N9+P9 -> 113102 | S9: =E9+G9+K9+I9+M9+O9+Q9 -> 77 | T9: =R9-S9 -> 113025 | U9: =S9/R9 -> 0.0006808014
A10: 6 | B10: 25 | C10: Bahi Dar | D10: ='B-Dar'!F235 -> 1565 | E10: ='B-Dar'!G240 -> 12 | F10: ='B-Dar'!G235 -> 8851 | G10: ='B-Dar'!G241 -> 16 | H10: ='B-Dar'!H235 -> 44 | I10: ='B-Dar'!G242 -> 2 | J10: ='B-Dar'!I235 -> 12 | K10: ='B-Dar'!G243 -> 11 | L10: ='B-Dar'!J235 -> 25540 | M10: ='B-Dar'!G244 -> 1126 | N10: ='B-Dar'!K235 -> 345 | O10: ='B-Dar'!G245 -> 0 | P10: ='B-Dar'!L235 -> 4342 | Q10: ='B-Dar'!G246 -> 252 | R10: =D10+F10+H10+J10+L10+N10+P10 -> 40699 | S10: =E10+G10+K10+I10+M10+O10+Q10 -> 1419 | T10: =R10-S10 -> 39280 | U10: =S10/R10 -> 0.034865722
A11: 7 | B11: 11 | C11: Dessie | D11: =Desie!F161 -> 1105 | E11: =Desie!G167 -> 0 | F11: =Desie!G161 -> 2660 | G11: =Desie!G168 -> 20 | H11: =Desie!H161 -> 28 | I11: =Desie!G169 -> 2 | J11: =Desie!I161 -> 3434 | K11: =Desie!G170 -> 52 | L11: =Desie!J161 -> 13815 | M11: =Desie!G171 -> 240 | N11: =Desie!K161 -> 1 | O11: =Desie!G172 -> 0 | P11: =Desie!L161 -> 268 | Q11: =Desie!G173 -> 49 | R11: =D11+F11+H11+J11+L11+N11+P11 -> 21311 | S11: =E11+G11+K11+I11+M11+O11+Q11 -> 363 | T11: =R11-S11 -> 20948 | U11: =S11/R11 -> 0.017033457
A12: 8 | B12: 17 | C12: DIREDAWA | D12: ='Dire Dawa'!E92 -> 1366 | E12: ='Dire Dawa'!O98 -> 0 | F12: ='Dire Dawa'!F92 -> 8041 | G12: ='Dire Dawa'!O99 -> 0 | H12: ='Dire Dawa'!G92 -> 4 | I12: ='Dire Dawa'!O100 -> 0 | J12: ='Dire Dawa'!H92 -> 1171 | K12: ='Dire Dawa'!O101 -> 0 | L12: ='Dire Dawa'!I92 -> 24004 | M12: ='Dire Dawa'!O102 -> 0 | N12: ='Dire Dawa'!J92 -> 0 | O12: ='Dire Dawa'!O103 -> 0 | P12: ='Dire Dawa'!K92 -> 240 | Q12: ='Dire Dawa'!O104 -> 0 | R12: =D12+F12+H12+J12+L12+N12+P12 -> 34826 | S12: =E12+G12+K12+I12+M12+O12+Q12 -> 0 | T12: =R12-S12 -> 34826 | U12: =S12/R12 -> 0
A13: 9 | B13: 39 | C13: Hawassa | D13: =Hawassa!G297 -> 3320 | E13: =Hawassa!J300 -> 0 | F13: =Hawassa!H297 -> 29868 | G13: =Hawassa!J301 -> 0 | H13: =Hawassa!I297 -> 94 | I13: =Hawassa!J302 -> 0 | J13: =Hawassa!J297 -> 130 | K13: =Hawassa!J303 -> 0 | L13: =Hawassa!K297 -> 18486 | M13: =Hawassa!J304 -> 0 | N13: =Hawassa!L297 -> 1 | O13: =Hawassa!J305 -> 0 | P13: =Hawassa!M297 -> 582 | Q13: =Hawassa!J306 -> 0 | R13: =D13+F13+H13+J13+L13+N13+P13 -> 52481 | S13: =E13+G13+K13+I13+M13+O13+Q13 -> 0 | T13: =R13-S13 -> 52481 | U13: =S13/R13 -> 0
A14: 10 | B14: 36 | C14: Hossaena | D14: =Hossaena!F209 -> 5961 | E14: =Hossaena!G214 -> 1 | F14: =Hossaena!G209 -> 47643 | G14: =Hossaena!G215 -> 8 | H14: =Hossaena!H209 -> 40 | I14: =Hossaena!G216 -> 0 | J14: =Hossaena!I209 -> 164 | K14: =Hossaena!G217 -> 98 | L14: =Hossaena!J209 -> 121170 | M14: =Hossaena!G218 -> 968 | N14: =Hossaena!K209 -> 1 | O14: =Hossaena!G219 -> 1 | P14: =Hossaena!L209 -> 234 | Q14: =Hossaena!G220 -> 206 | R14: =D14+F14+H14+J14+L14+N14+P14 -> 175213 | S14: =E14+G14+K14+I14+M14+O14+Q14 -> 1282 | T14: =R14-S14 -> 173931 | U14: =S14/R14 -> 0.0073168087
A15: 11 | B15: 26 | C15: Wolkite | D15: =Wolkite!E185 -> 225 | E15: =Wolkite!F194 -> 3 | F15: =Wolkite!F185 -> 16435 | G15: =Wolkite!F195 -> 10 | H15: =Wolkite!G185 -> 42 | I15: =Wolkite!F196 -> 2 | J15: =Wolkite!H185 -> 294 | K15: =Wolkite!F197 -> 125 | L15: =Wolkite!I185 -> 53926 | M15: =Wolkite!F198 -> 107 | N15: =Wolkite!J185 -> 0 | O15: =Wolkite!F199 -> 0 | P15: =Wolkite!K185 -> 101 | Q15: =Wolkite!F200 -> 11 | R15: =D15+F15+H15+J15+L15+N15+P15 -> 71023 | S15: =E15+G15+K15+I15+M15+O15+Q15 -> 258 | T15: =R15-S15 -> 70765 | U15: =S15/R15 -> 0.0036326261
A16: 12 | B16: 20 | C16: Jimma | D16: =Jimma!G126 -> 129 | E16: =Jimma!L135 -> 0 | F16: =Jimma!H126 -> 4114 | G16: =Jimma!L136 -> 0 | H16: =Jimma!I126 -> 32 | I16: =Jimma!L137 -> 0 | J16: =Jimma!J126 -> 3238 | K16: =Jimma!L138 -> 0 | L16: =Jimma!K139 -> 62264 | M16: =Jimma!L140 -> 0 | N16: =Jimma!L126 -> 16 | O16: =Jimma!L140 -> 0 | P16: =Jimma!M126 -> 300 | Q16: =Jimma!L141 -> 0 | R16: =D16+F16+H16+J16+L16+N16+P16 -> 70093 | S16: =E16+G16+K16+I16+M16+O16+Q16 -> 0 | T16: =R16-S16 -> 70093
A17: 13 | B17: 7 | C17: Mekelle | D17: =Mekelle!E26 -> 0 | E17: =Mekelle!F36 -> 0 | F17: =Mekelle!F26 -> 1536 | G17: =Mekelle!F37 -> 2 | H17: =Mekelle!G26 -> 0 | I17: =Mekelle!F38 -> 0 | J17: =Mekelle!H26 -> 0 | K17: =Mekelle!F39 -> 0 | L17: =Mekelle!I26 -> 6357 | M17: =Mekelle!F40 -> 87 | N17: =Mekelle!J26 -> 13 | O17: =Mekelle!F41 -> 0 | P17: =Mekelle!K26 -> 6 | Q17: =Mekelle!F42 -> 3 | R17: =D17+F17+H17+J17+L17+N17+P17 -> 7912 | S17: =E17+G17+K17+I17+M17+O17+Q17 -> 92 | T17: =R17-S17 -> 7820 | U17: =S17/R17 -> 0.011627907
B18: =SUM(B5:B17) -> 427 | C18: TOTAL | D18: =SUM(D5:D17) -> 33980 | E18: =SUM(E5:E17) -> 126 | F18: =SUM(F5:F17) -> 224627 | G18: =SUM(G5:G17) -> 105 | H18: =SUM(H5:H17) -> 1126 | I18: =SUM(I5:I17) -> 33 | J18: =SUM(J5:J17) -> 30321 | K18: =SUM(K5:K17) -> 443 | ... Q18: =SUM(Q5:Q17) -> 875 | R18: =D18+F18+H18+J18+L18+N18+P18 -> 1088057 | S18: =SUM(S5:S17) -> 4259 | T18: =SUM(T5:T17) -> 1083798 | U18: =SUM(U5:U17) -> 0.082291069
E19: =D18-E18 -> 33854 | G19: =F18-G18 -> 224522 | I19: =H18-I18 -> 1093 | K19: =J18-K18 -> 29878 | M19: =L18-M18 -> 782056 | O19: =N18-O18 -> 5159 | Q19: =Q18/P18 -> 0.10787819
C21: Current | E21: Previous
C22: No. of inactive balance account | E22: No. of inactive balance account
G23: Weekly rectification
C24: Unrectified | D24: Rectified | E24: Unrectified | F24: Rectified | G24: Unrectified | H24: Rectified
B25: East | G25: =C25-E25 -> 0 | H25: =D25-F25 -> 0
B26: North | G26: =C26-E26 -> 0 | H26: =D26-F26 -> 0
B27: South | G27: =C27-E27 -> 0 | H27: =D27-F27 -> 0
B28: West | G28: =C28-E28 -> 0 | H28: =D28-F28 -> 0
B29: Adama | G29: =C29-E29 -> 0 | H29: =D29-F29 -> 0
B30: Bahi Dar | G30: =C30-E30 -> 0 | H30: =D30-F30 -> 0
B31: Dessie | G31: =C31-E31 -> 0 | H31: =D31-F31 -> 0
B32: DIREDAWA | G32: =C32-E32 -> 0 | H32: =D32-F32 -> 0
B33: Hawassa | G33: =C33-E33 -> 0 | H33: =D33-F33 -> 0
B34: Hossaena | G34: =C34-E34 -> 0 | H34: =D34-F34 -> 0
B35: Wolkite | G35: =C35-E35 -> 0 | H35: =D35-F35 -> 0
B36: Jimma | G36: =C36-E36 -> 0 | H36: =D36-F36 -> 0
B37: Mekelle | G37: =C37-E37 -> 0 | H37: =D37-F37 -> 0
C38: =SUM(C25:C37) -> 0 | D38: =SUM(D25:D37) -> 0 | G38: =SUM(G25:G37) -> 0 | H38: =SUM(H25:H37) -> 0
D39: =C38-D38 -> 0 | F39: =E38-F38 -> 0

Sheet Summarised
A1: Monthly Controllers report as at july 2026
A2: SN | B2: Total No. of Branches | C2: District | D2: ATM Cases | F2: IT Case | G2: No. of zero balance account | H2: No. of inactive balance account | I2: Cheque Book case | J2: Others Case No | K2: Amount involved in Birr | L2: Status of the irregularities | O2: No. of Branches not dispatched | P2: No. of Branches Dispatched reports | Q2: Total No. of cases
D3: Mismatch | E3: Long outstanding | L3: Unrectified | M3: Rectified | N3: rectified percetage
B4: A | C4: B | J4: D | K4: E | L4: F | M4: G | O4: I | P4: I
A5: 1 | B5: 49 | C5: East | D5: ='Case Summarised'!D5 -> 0 | E5: ='Case Summarised'!F5 -> 25057 | F5: ='Case Summarised'!H5 -> 135 | G5: ='Case Summarised'!J5 -> 3973 | H5: ='Case Summarised'!L5 -> 87889 | I5: ='Case Summarised'!N5 -> 49 | J5: ='Case Summarised'!P5 -> 625 | K5: =East!N760 -> 1.484968e+09 | L5: =D5+E5+F5+G5+H5+I5+J5 -> 117728 | M5: ='Case Summarised'!Q5 -> 241 | N5: =M5/J5 -> 0.3856 | O5: 1 | P5: =B5-O5 -> 48 | Q5: =D5+E5+F5+G5+H5+I5+J5 -> 117728
A6: 2 | B6: 42 | C6: North | D6: ='Case Summarised'!D6 -> 5283 | E6: ='Case Summarised'!F6 -> 16438 | F6: ='Case Summarised'!H6 -> 129 | G6: ='Case Summarised'!J6 -> 6798 | H6: ='Case Summarised'!L6 -> 27137 | I6: ='Case Summarised'!N6 -> 990 | J6: ='Case Summarised'!P6 -> 228 | K6: =North!N377 -> 3.6939536e+09 | L6: =D6+E6+F6+G6+H6+I6+J6 -> 57003 | M6: ='Case Summarised'!Q6 -> 65 | N6: =M6/J6 -> 0.28508772 | O6: 2 | P6: =B6-O6 -> 40 | Q6: =D6+E6+F6+G6+H6+I6+J6 -> 57003
A7: 3 | B7: 57 | C7: South | D7: ='Case Summarised'!D7 -> 8018 | E7: ='Case Summarised'!F7 -> 27504 | F7: ='Case Summarised'!H7 -> 312 | G7: ='Case Summarised'!J7 -> 9969 | H7: ='Case Summarised'!L7 -> 158159 | I7: ='Case Summarised'!N7 -> 971 | J7: ='Case Summarised'!P7 -> 818 | K7: =South!N1066 -> -3.2776797e+09 | L7: =D7+E7+F7+G7+H7+I7+J7 -> 205751 | M7: ='Case Summarised'!Q7 -> 8 | N7: =M7/J7 -> 0.0097799511 | O7: 1 | P7: =B7-O7 -> 56 | Q7: =D7+E7+F7+G7+H7+I7+J7 -> 205751
A8: 4 | B8: 57 | C8: West | D8: ='Case Summarised'!D8 -> 5776 | E8: ='Case Summarised'!F8 -> 19909 | F8: ='Case Summarised'!H8 -> 193 | G8: ='Case Summarised'!J8 -> 864 | H8: ='Case Summarised'!L8 -> 91240 | I8: ='Case Summarised'!N8 -> 2773 | J8: ='Case Summarised'!P8 -> 160 | K8: =West!N514 -> 3.9882254e+09 | L8: =D8+E8+F8+G8+H8+I8+J8 -> 120915 | M8: ='Case Summarised'!Q8 -> 20 | N8: =M8/J8 -> 0.125 | O8: 1 | P8: =B8-O8 -> 56 | Q8: =D8+E8+F8+G8+H8+I8+J8 -> 120915
A9: 5 | B9: 33 | C9: Adama | D9: ='Case Summarised'!D9 -> 1232 | E9: ='Case Summarised'!F9 -> 16571 | F9: ='Case Summarised'!H9 -> 73 | G9: ='Case Summarised'!J9 -> 274 | H9: ='Case Summarised'!L9 -> 94745 | I9: ='Case Summarised'!N9 -> 0 | J9: ='Case Summarised'!P9 -> 207 | K9: =Adama!N282 -> 1.0649864e+09 | L9: =D9+E9+F9+G9+H9+I9+J9 -> 113102 | M9: ='Case Summarised'!Q9 -> 20 | N9: =M9/J9 -> 0.096618357 | O9: 6 | P9: =B9-O9 -> 27 | Q9: =D9+E9+F9+G9+H9+I9+J9 -> 113102
A10: 6 | B10: 25 | C10: Bahi Dar | D10: ='Case Summarised'!D10 -> 1565 | E10: ='Case Summarised'!F10 -> 8851 | F10: ='Case Summarised'!H10 -> 44 | G10: ='Case Summarised'!J10 -> 12 | H10: ='Case Summarised'!L10 -> 25540 | I10: ='Case Summarised'!N10 -> 345 | J10: ='Case Summarised'!P10 -> 4342 | K10: ='B-Dar'!M235 -> 5.0140589e+08 | L10: =D10+E10+F10+G10+H10+I10+J10 -> 40699 | M10: ='Case Summarised'!Q10 -> 252 | N10: =M10/J10 -> 0.058037771 | O10: 1 | P10: =B10-O10 -> 24 | Q10: =D10+E10+F10+G10+H10+I10+J10 -> 40699
A11: 7 | B11: 11 | C11: Dessie | D11: ='Case Summarised'!D11 -> 1105 | E11: ='Case Summarised'!F11 -> 2660 | F11: ='Case Summarised'!H11 -> 28 | G11: ='Case Summarised'!J11 -> 3434 | H11: ='Case Summarised'!L11 -> 13815 | I11: ='Case Summarised'!N11 -> 1 | J11: ='Case Summarised'!P11 -> 268 | K11: =Desie!M161 -> 1.1208084e+08 | L11: =D11+E11+F11+G11+H11+I11+J11 -> 21311 | M11: ='Case Summarised'!Q11 -> 49 | N11: =M11/J11 -> 0.18283582 | P11: =B11-O11 -> 11 | Q11: =D11+E11+F11+G11+H11+I11+J11 -> 21311
A12: 8 | B12: 18 | C12: DIREDAWA | D12: ='Case Summarised'!D12 -> 1366 | E12: ='Case Summarised'!F12 -> 8041 | F12: ='Case Summarised'!H12 -> 4 | G12: ='Case Summarised'!J12 -> 1171 | H12: ='Case Summarised'!L12 -> 24004 | I12: ='Case Summarised'!N12 -> 0 | J12: ='Case Summarised'!P12 -> 240 | K12: ='Dire Dawa'!N92 -> -1.3426429e+08 | L12: =D12+E12+F12+G12+H12+I12+J12 -> 34826 | M12: ='Case Summarised'!Q12 -> 0 | N12: =M12/J12 -> 0 | O12: 11 | P12: =B12-O12 -> 7 | Q12: =D12+E12+F12+G12+H12+I12+J12 -> 34826
A13: 9 | B13: 39 | C13: Hawassa | D13: ='Case Summarised'!D13 -> 3320 | E13: ='Case Summarised'!F13 -> 29868 | F13: ='Case Summarised'!H13 -> 94 | G13: ='Case Summarised'!J13 -> 130 | H13: ='Case Summarised'!L13 -> 18486 | I13: ='Case Summarised'!N13 -> 1 | J13: ='Case Summarised'!P13 -> 582 | K13: =Hawassa!N297 -> 5.8689031e+08 | L13: =D13+E13+F13+G13+H13+I13+J13 -> 52481 | M13: ='Case Summarised'!Q13 -> 0 | N13: =M13/J13 -> 0 | O13: 5 | P13: =B13-O13 -> 34 | Q13: =D13+E13+F13+G13+H13+I13+J13 -> 52481
A14: 10 | B14: 36 | C14: Hossaena | D14: ='Case Summarised'!D14 -> 5961 | E14: ='Case Summarised'!F14 -> 47643 | F14: ='Case Summarised'!H14 -> 40 | G14: ='Case Summarised'!J14 -> 164 | H14: ='Case Summarised'!L14 -> 121170 | I14: ='Case Summarised'!N14 -> 1 | J14: ='Case Summarised'!P14 -> 234 | K14: =Hossaena!M209 -> 22785826 | L14: =D14+E14+F14+G14+H14+I14+J14 -> 175213 | M14: ='Case Summarised'!Q14 -> 206 | N14: =M14/J14 -> 0.88034188 | O14: 5 | P14: =B14-O14 -> 31 | Q14: =D14+E14+F14+G14+H14+I14+J14 -> 175213
A15: 11 | B15: 26 | C15: Wolkite | D15: ='Case Summarised'!D15 -> 225 | E15: ='Case Summarised'!F15 -> 16435 | F15: ='Case Summarised'!H15 -> 42 | G15: ='Case Summarised'!J15 -> 294 | H15: ='Case Summarised'!L15 -> 53926 | I15: ='Case Summarised'!N15 -> 0 | J15: ='Case Summarised'!P15 -> 101 | K15: =Wolkite!N185 -> 92500185 | L15: =D15+E15+F15+G15+H15+I15+J15 -> 71023 | M15: ='Case Summarised'!Q15 -> 11 | N15: =M15/J15 -> 0.10891089 | O15: 3 | P15: =B15-O15 -> 23 | Q15: =D15+E15+F15+G15+H15+I15+J15 -> 71023
A16: 12 | B16: 20 | C16: Jimma | D16: ='Case Summarised'!D16 -> 129 | E16: ='Case Summarised'!F16 -> 4114 | F16: ='Case Summarised'!H16 -> 32 | G16: ='Case Summarised'!J16 -> 3238 | H16: ='Case Summarised'!L16 -> 62264 | I16: ='Case Summarised'!N16 -> 16 | J16: ='Case Summarised'!P16 -> 300 | K16: =Jimma!N126 -> 1.4931622e+08 | L16: =D16+E16+F16+G16+H16+I16+J16 -> 70093 | M16: ='Case Summarised'!Q16 -> 0 | O16: 14 | P16: =B16-O16 -> 6 | Q16: =D16+E16+F16+G16+H16+I16+J16 -> 70093
A17: 13 | B17: 11 | C17: Mekelle | D17: ='Case Summarised'!D17 -> 0 | E17: ='Case Summarised'!F17 -> 1536 | F17: ='Case Summarised'!H17 -> 0 | G17: ='Case Summarised'!J17 -> 0 | H17: ='Case Summarised'!L17 -> 6357 | I17: ='Case Summarised'!N17 -> 13 | J17: ='Case Summarised'!P17 -> 6 | K17: =Mekelle!N26 -> 21633865 | L17: =D17+E17+F17+G17+H17+I17+J17 -> 7912 | M17: ='Case Summarised'!Q17 -> 3 | N17: =M17/J17 -> 0.5 | P17: =B17-O17 -> 11 | Q17: =D17+E17+F17+G17+H17+I17+J17 -> 7912
B18: =SUM(B5:B17) -> 424 | C18: TOTAL | D18: =SUM(D5:D17) -> 33980 | E18: ='Case Summarised'!F18 -> 224627 | F18: ='Case Summarised'!H18 -> 1126 | G18: ='Case Summarised'!J18 -> 30321 | H18: ='Case Summarised'!L18 -> 784732 | I18: ='Case Summarised'!N18 -> 5160 | J18: ='Case Summarised'!P18 -> 8111 | K18: =SUM(K5:K17) -> 8.3068025e+09 | L18: =D18+E18+F18+G18+H18+I18+J18 -> 1088057 | M18: ='Case Summarised'!Q18 -> 875 | N18: =M18/J18 -> 0.10787819 | O18: =SUM(O5:O17) -> 50 | P18: =B18-O18 -> 374 | Q18: =D18+E18+F18+G18+H18+I18+J18 -> 1088057
O19: =O18/B18 -> 0.11792453 | P19: =P18/B18 -> 0.88207547

Sheet East
B1: NIB International Bank S.C
B2: Monthly internal Control Reports
B3: As of July 31, 2026
A4: Ser.No | B4: Branch | C4: District | D4: Operation area | E4: ATM Cases | G4: It Case | H4: Zero Balance | I4: Dormant A/C | J4: Cheque Bok Case | K4: Other cases | L4: Posting Date | M4: Types of Irregularities/problems | N4: Amount involved | O4: Status of the irregularities
D5: Operation area | E5: Mismatch | F5: Long outstanding | K5: finding NO. | M5: Finding | O5: Unrectified | P5: Rectified | Q5: Unrectified In Amount
A6: 1 | B6: ARABSSA | C6: East district | D6: Cash and Cash Items | K6: 1 | L6: JULY 31,2026 | M6: Difference observed on ATM cash balance.(The physical cash count balance of ATM have shown a difference of Birr compared with the general ledger balance . ) | N6: -12403.62 | O6: 1
A7: 2 | B7: ARABSSA | C7: East district | D7: Account Management | G7: 1 | L7: october 10,2021 | M7: System suspense account AC | N7: 1087.8 | O7: 1
A8: 3 | B8: ARABSSA | C8: East district | D8: Account Management | G8: 1 | L8: october 10,2021 | M8: Migration suspense accounts | N8: 0.48 | O8: 1
A9: 4 | B9: ARABSSA | C9: East district | D9: Deposit Accounts | H9: 37 | L9: JULY 31,2026 | M9: Zero (0.00) balance Account Found at branch | O9: 37 | P9: 35
A10: 5 | B10: ARABSSA | C10: East district | D10: Deposit Accounts | I10: 827 | L10: JULY 31,2026 | M10: Dormant accounts Found at the branch | N10: 509552.22 | O10: 827
A11: 6 | B11: ARABSSA | C11: East district | D11: Card Banking | F11: 354 | L11: JULY 31,2026 | M11: ATM cards & PIN mailers were not delivered to the respective account holders/ customers for a long period of time as presented below. 354 Card & 22 PIN | O11: 354
A12: 7 | B12: ARABSSA | C12: East district | D12: Ticket Vouching | K12: 1 | L12: JULY 6,2026 | M12: Diposit vocher missing date | N12: 4000 | O12: 1 | P12: 1
A13: 8 | B13: ARABSSA | C13: East district | D13: Ticket Vouching | K13: 1 | L13: JULY 8,2026 | M13: fund transfer missing signaature | N13: 10000 | O13: 1
A14: 9 | B14: ARABSSA | C14: East district | D14: Ticket Vouching | K14: 1 | L14: JULY 17,2026 | M14: Missing date in withdrawal voucher | N14: 6000 | O14: 1 | P14: 1
A15: 10 | B15: ARABSSA | C15: East district | D15: Ticket Vouching | K15: 1 | L15: JULY 25,2026 | M15: Withddrawal vocher in word&f igure d/c | N15: 2000 | O15: 1 | P15: 1
A16: 11 | B16: AYAT 72 | C16: East district | D16: Cash and Cash Items | K16: 1 | M16: Abnormal balances of ATM cash | N16: 34700 | O16: 1
A17: 12 | B17: AYAT 72 | C17: East district | D17: Account Management | G17: 1 | M17: Inter branch T-24 R10 | N17: -9282596.8 | O17: 1
A18: 13 | B18: AYAT 72 | C18: East district | D18: Account Management | G18: 1 | M18: Migration suspense accounts | N18: 4611.81 | O18: 1
A19: 14 | B19: AYAT 72 | C19: East district | G19: 1 | M19: Catch all asset and liability | N19: 591.07 | O19: 1 | P19: 1
A20: 15 | B20: AYAT 72 | C20: East district | D20: Account Management | K20: 1 | M20: Sundry creditors | N20: -3193 | O20: 1
A21: 16 | B21: AYAT 72 | C21: East district | D21: Deposit Accounts | I21: 262 | M21: Dormant accounts Found at the branch | O21: 262
A22: 17 | B22: AYAT 72 | C22: East district | D22: Card Banking | F22: 278 | M22: ATM cards & PIN mailers were not delivered to the respective account holders/ customers for a long period of time as presented below. | N22: 2700 | O22: 278 | P22: 1
A23: 18 | B23: AYAT 72 | C23: East district | D23: =D24 -> Ticket Vouching | K23: 1 | L23: 46029 | M23: Ato addis ashenafi acc transfe wrong date 150USD | N23: 150 | O23: 1 | P23: 1
A24: 19 | B24: AYAT 72 | C24: East district | D24: =D25 -> Ticket Vouching | K24: =K23 -> 1 | L24: 46029 | M24: cash withdrawal with wrong year but | N24: 5000 | O24: 1 | P24: 1
A25: 20 | B25: AYAT 72 | C25: East district | D25: =D26 -> Ticket Vouching | K25: =K24 -> 1 | L25: 46060 | M25: tsedenia manaye cash deposit date error | N25: 15000 | O25: 1 | P25: 1
A26: 21 | B26: AYAT 72 | C26: East district | D26: =D27 -> Ticket Vouching | K26: =K25 -> 1 | L26: 46060 | M26: tsedenia manaye acc transfer date error | N26: 10000 | O26: 1 | P26: 1
A27: 22 | B27: AYAT 72 | C27: East district | D27: =D28 -> Ticket Vouching | K27: =K26 -> 1 | L27: 46210 | M27: cash withdrawal with out customer signatuer | N27: 1100 | O27: 1 | P27: 1
A28: 23 | B28: AYAT 72 | C28: East district | D28: =D30 -> Ticket Vouching | K28: =K29 -> 1 | L28: 21/07/26 | M28: cash withdrawal with out customer signature | N28: 1050 | O28: 1 | P28: 1
A29: 24 | B29: AYAT 72 | C29: East district | D29: =D28 -> Ticket Vouching | K29: =K30 -> 1 | L29: 24/07/26 | M29: cash withdrawal with wrong date | N29: 100 | O29: 1 | P29: 1
A30: 25 | B30: AYAT 72 | C30: East district | D30: Ticket Vouching | K30: 1 | L30: 23/07/26 | M30: cash withdrawal with customer signature error | N30: 2000 | O30: 1 | P30: 1
A31: 26 | B31: AYAT ADEBABAY | C31: East district | D31: Account Management | G31: 1 | M31: Inter branch T-24 R10 | N31: -1.0536097e+08 | O31: 1
A32: 27 | B32: AYAT ADEBABAY | C32: East district | D32: Account Management | G32: 1 | M32: Migration suspense accounts | N32: -2634499.9 | O32: 1
A33: 28 | B33: AYAT ADEBABAY | C33: East district | K33: 1 | M33: Un collected Service fee on RTGS transfer from customers in Nov 2022 | N33: 1150 | O33: 1
A34: 29 | B34: AYAT ADEBABAY | C34: East district | D34: Deposit Accounts | H34: 433 | M34: Zero (0.00) balance Account Found at branch | O34: 433 | P34: 21
A35: 30 | B35: AYAT ADEBABAY | C35: East district | D35: Deposit Accounts | I35: 109 | M35: Dormant accounts Found at the branch | N35: 3752611.3 | O35: 109
A36: 31 | B36: AYAT ADEBABAY | C36: East district | D36: Card Banking | F36: 722 | M36: ATM cards & PIN mailers were not delivered to the respective account holders/ customers for a long period of time.(691 Cards & 722 Pins) | N36: - | O36: 722
A37: 32 | B37: AYAT ADEBABAY | C37: East district | D37: Loan and Advances | K37: 3 | M37: Loans with Arears | N37: 2345481 | O37: 3
A38: 33 | B38: AYAT ADEBABAY | C38: East district | D38: Ticket Vouching | K38: 1 | L38: 46180 | M38: Date error made on cash withdrawal voucher | N38: 7500 | O38: 1 | P38: 1
A39: 34 | B39: AYAT ADEBABAY | C39: East district | D39: Ticket Vouching | K39: 1 | L39: 46363 | M39: Date error made on cash withdrawal voucher | N39: 600 | O39: 1
A40: 35 | B40: AYAT ADEBABAY | C40: East district | D40: Ticket Vouching | K40: 1 | L40: 24/7/2026 | M40: Amount in words not written in cash withdrawal Voucherform | N40: 3300 | O40: 1
...

Sheet North
A1: NIB International Bank S.C
A2: North A.A District
A3: Detailed Monthly internal Control Reports
A4: As of JULY, 2026
A5: Ser. No | B5: Branch Name | C5: District Name | D5: Operation area | E5: Date | F5: Types of Irregularities/problems | G5: ATM Cases | I5: 0 | J5: 0 | K5: 0 | L5: 0 | M5: Other Case No. | N5: Amount involved | O5: status of irregularity | P5: 0
F6: Finding | G6: Mismatch | H6: Long O/S | I6: IT Cases | J6: Zero Bal. | K6: Dormant A/C | L6: CK Book | M6: 0 | N6: 0 | O6: Unrectified | P6: Rectified
A7: 1 | B7: Abakoran | C7: North A.A | D7: Cash & Cash Items | E7: 31/07/2026 | F7: Difference observed on ATM cash balance.(The physical cash count balance of ATM (240,300) have shown a difference of Birr 15,598.34 compared with the general ledger balance .(255,898.34) | G7: 0 | H7: 0 | I7: 0 | J7: 0 | K7: 0 | L7: 0 | M7: 1 | N7: 15598.34 | O7: =G7+H7+I7+J7+K7+L7+M7-P7 -> 1 | P7: 0
A8: 2 | B8: Abakoran | C8: North A.A | D8: Negotiable Instrument | E8: 31/07/2025 | F8: Cheque books prepared but not delivered to customers for a long period of time. | G8: 0 | H8: 0 | I8: 0 | J8: 0 | K8: 0 | L8: 51 | M8: 0 | N8: 0 | O8: =G8+H8+I8+J8+K8+L8+M8-P8 -> 51 | P8: 0
A9: 3 | B9: Abakoran | C9: North A.A | D9: Account Management | E9: 31/07/25 | F9: Inter branch T-24 R10 | G9: 0 | H9: 0 | I9: 1 | J9: 0 | K9: 0 | L9: 0 | M9: 0 | N9: -77522181 | O9: =G9+H9+I9+J9+K9+L9+M9-P9 -> 1 | P9: 0
A10: 4 | B10: Abakoran | C10: North A.A | D10: Account Management | E10: 31/07/25 | F10: Migration suspense accounts | G10: 0 | H10: 0 | I10: 1 | J10: 0 | K10: 0 | L10: 0 | M10: 0 | N10: 113922.37 | O10: =G10+H10+I10+J10+K10+L10+M10-P10 -> 1 | P10: 0
A11: 5 | B11: Abakoran | C11: North A.A | D11: Account Management | E11: 31/08/2025 | F11: Sundry debtors | G11: 0 | H11: 0 | I11: 0 | J11: 0 | K11: 0 | L11: 0 | M11: 3 | N11: 194773.41 | O11: =G11+H11+I11+J11+K11+L11+M11-P11 -> 3 | P11: 0
A12: 6 | B12: Abakoran | C12: North A.A | D12: Loan and Advances | E12: 31/08/2026 | F12: arrears loan show on the branch and NPL for long period of time | G12: 0 | H12: 0 | I12: 0 | J12: 0 | K12: 0 | L12: 0 | M12: 5 | N12: 1601059.5 | O12: =G12+H12+I12+J12+K12+L12+M12-P12 -> 5 | P12: 0
A13: 7 | B13: Abakoran | C13: North A.A | D13: Deposit Account | E13: 31/08/2026 | F13: Zero (0.00) balance Account Found at branch | G13: 0 | H13: 0 | I13: 0 | J13: 124 | K13: 0 | L13: 0 | M13: 0 | N13: 0 | O13: =G13+H13+I13+J13+K13+L13+M13-P13 -> 124 | P13: 0
A14: 8 | B14: Abakoran | C14: North A.A | D14: Deposit Account | E14: 31/07/2026 | F14: Dormant accounts Found at the branch | G14: 0 | H14: 0 | I14: 0 | J14: 0 | K14: 503 | L14: 0 | M14: 0 | N14: 3190418.7 | O14: =G14+H14+I14+J14+K14+L14+M14-P14 -> 500 | P14: 3
A15: 9 | B15: Abakoran | C15: North A.A | D15: Fixed Asset Management | E15: 31/07/2026 | F15: Absence of tag number | G15: 0 | H15: 0 | I15: 0 | J15: 0 | K15: 0 | L15: 0 | M15: 4 | N15: 0 | O15: =G15+H15+I15+J15+K15+L15+M15-P15 -> 0 | P15: 4
A16: 10 | B16: Abakoran | C16: North A.A | D16: Fixed Asset Management | E16: 31/08/2026 | F16: Defective/obsolete fixed assets found at the branch | G16: 0 | H16: 0 | I16: 0 | J16: 0 | K16: 0 | L16: 0 | M16: 4 | N16: 0 | O16: =G16+H16+I16+J16+K16+L16+M16-P16 -> 0 | P16: 4
A17: 11 | B17: Abakoran | C17: North A.A | D17: Card Banking | E17: 31/08/2026 | F17: ATM cards & PIN mailers were not delivered to the respective account holders/ customers for a long period of time as presented below. | G17: 0 | H17: 321 | I17: 0 | J17: 0 | K17: 0 | L17: 0 | M17: 0 | N17: 0 | O17: =G17+H17+I17+J17+K17+L17+M17-P17 -> 321 | P17: 0
A18: 12 | B18: Abakoran | C18: North A.A | D18: Card Banking | E18: 31/08/2026 | F18: ATM card(321) and PIN Mailers(105) were differ | G18: =321-105 -> 216 | H18: 0 | I18: 0 | J18: 0 | K18: 0 | L18: 0 | M18: 0 | N18: 0 | O18: =G18+H18+I18+J18+K18+L18+M18-P18 -> 216 | P18: 0
A19: 13 | B19: Abakoran | C19: North A.A | D19: Ticket Vouching | E19: 31/08/2026 | F19: Cash withdrawal Without Signature | G19: 0 | H19: 0 | I19: 0 | J19: 0 | K19: 0 | L19: 0 | M19: 1 | N19: 40000 | O19: =G19+H19+I19+J19+K19+L19+M19-P19 -> 0 | P19: 1
A20: 14 | B20: Abakoran | C20: North A.A | D20: Ticket Vouching | E20: 31/08/2026 | F20: RTGS without signature | G20: 0 | H20: 0 | I20: 0 | J20: 0 | K20: 0 | L20: 0 | M20: 5 | N20: 16580000 | O20: =G20+H20+I20+J20+K20+L20+M20-P20 -> 0 | P20: 5
A21: 15 | B21: Abakoran | C21: North A.A | D21: Ticket Vouching | E21: 31/08/2026 | F21: Account transfer without signature | G21: 0 | H21: 0 | I21: 0 | J21: 0 | K21: 0 | L21: 0 | M21: 7 | N21: 4385300 | O21: =G21+H21+I21+J21+K21+L21+M21-P21 -> 0 | P21: 7
A22: 16 | B22: Abakoran | C22: North A.A | D22: Others | E22: 26/12/25 | F22: Catch All - Unassigned PL | G22: 0 | H22: 0 | I22: 1 | J22: 0 | K22: 0 | L22: 0 | M22: 0 | N22: 3128.32 | O22: =G22+H22+I22+J22+K22+L22+M22-P22 -> 1 | P22: 0
A23: 17 | B23: Adidisu Gebeya | C23: North A.A | D23: Cash & Cash Items | E23: 30/6/26 | F23: Difference observed on ATM cash balance.(The physical cash count balance of ATM have shown a difference of Birr ……….. compared with the general ledger balance . ) | G23: 0 | H23: 0 | I23: 0 | J23: 0 | K23: 0 | L23: 0 | M23: 1 | N23: 23500 | O23: =G23+H23+I23+J23+K23+L23+M23-P23 -> 1 | P23: 0
A24: 18 | B24: Adidisu Gebeya | C24: North A.A | D24: Account Management | E24: 30/6/26 | F24: Difference in non contingent | G24: 0 | H24: 0 | I24: 1 | J24: 0 | K24: 0 | L24: 0 | M24: 0 | N24: 930401 | O24: =G24+H24+I24+J24+K24+L24+M24-P24 -> 1 | P24: 0
A25: 19 | B25: Adidisu Gebeya | C25: North A.A | D25: Account Management | E25: 30/6/26 | F25: Inter branch T-24 R10 | G25: 0 | H25: 0 | I25: 1 | J25: 0 | K25: 0 | L25: 0 | M25: 0 | N25: 5516790.1 | O25: =G25+H25+I25+J25+K25+L25+M25-P25 -> 1 | P25: 0
A26: 20 | B26: Adidisu Gebeya | C26: North A.A | D26: Account Management | E26: 30/6/26 | F26: Sundry debtors (Loan Balance CorrectionExpense) | G26: 0 | H26: 0 | I26: 0 | J26: 0 | K26: 0 | L26: 0 | M26: 1 | N26: 758257.7 | O26: =G26+H26+I26+J26+K26+L26+M26-P26 -> 1 | P26: 0
A27: 21 | B27: Adidisu Gebeya | C27: North A.A | D27: Deposit Account | E27: 30/6/26 | F27: Dormant accounts Found at the branch | G27: 0 | H27: 0 | I27: 0 | J27: 0 | K27: 750 | L27: 0 | M27: 0 | N27: 14333701 | O27: =G27+H27+I27+J27+K27+L27+M27-P27 -> 748 | P27: 2
A28: 22 | B28: Amist Killo | C28: North A.A | D28: Account Management | E28: 44206 | F28: Inter branch T-24 R10 | G28: 0 | H28: 0 | I28: 1 | J28: 0 | K28: 0 | L28: 0 | M28: 0 | N28: 47868363 | O28: =G28+H28+I28+J28+K28+L28+M28-P28 -> 1 | P28: 0
A29: 23 | B29: Amist Killo | C29: North A.A | D29: Account Management | E29: 31/07/26 | F29: loss on A/L Revaluation | G29: 0 | H29: 0 | I29: 1 | J29: 0 | K29: 0 | L29: 0 | M29: 0 | N29: 75908.56 | O29: =G29+H29+I29+J29+K29+L29+M29-P29 -> 1 | P29: 0
A30: 24 | B30: Amist Killo | C30: North A.A | D30: Card Banking | E30: 31/07/26 | F30: Dormant accounts Found at the branch | G30: 0 | I30: 0 | J30: 0 | K30: 307 | L30: 0 | M30: 0 | N30: 112833 | O30: =G30+H30+I30+J30+K30+L30+M30-P30 -> 307 | P30: 0
A31: 25 | B31: Amist Killo | C31: North A.A | D31: Card Banking | E31: 45664 | F31: ATM cards & PIN mailers were not delivered to the respective account holders/ customers for a long period of time as presented below. | G31: 0 | H31: 897 | I31: 0 | J31: 0 | K31: 0 | L31: 0 | M31: 0 | N31: 0 | O31: =G31+H31+I31+J31+K31+L31+M31-P31 -> 897 | P31: 0
A32: 26 | B32: Amist Killo | C32: North A.A | D32: Card Banking | E32: 45664 | F32: ATM card(897) and PIN Mailers(278) were differ | G32: 619 | H32: 0 | I32: 0 | J32: 0 | K32: 0 | L32: 0 | M32: 0 | N32: 0 | O32: =G32+H32+I32+J32+K32+L32+M32-P32 -> 619 | P32: 0
A33: 27 | B33: Arada Giorgis | C33: North AA | D33: Cash and Cash Items | E33: 45863 | F33: Abnormal balances of ATM cash | G33: 0 | H33: 0 | I33: 0 | J33: 0 | K33: 0 | L33: 0 | M33: 1 | N33: 81.08 | O33: =G33+H33+I33+J33+K33+L33+M33-P33 -> 1 | P33: 0
A34: 28 | B34: Arada Giorgis | C34: North AA | D34: Cash & Cash Items | E34: 46081 | F34: Difference observed on ATM cash balance.(The physical cash count balance of ATM have shown a difference of Birr ……….. compared with the general ledger balance . ) | G34: 0 | H34: 0 | I34: 0 | J34: 0 | K34: 0 | L34: 0 | M34: 1 | N34: 35138.94 | O34: =G34+H34+I34+J34+K34+L34+M34-P34 -> 1 | P34: 0
A35: 29 | B35: Arada Giorgis | C35: North AA | D35: Account Management | E35: 45863 | F35: Inter branch T-24 R10 | G35: 0 | H35: 0 | I35: 1 | J35: 0 | K35: 0 | L35: 0 | M35: 0 | N35: 23705127 | O35: =G35+H35+I35+J35+K35+L35+M35-P35 -> 1 | P35: 0
A36: 30 | B36: Arada Giorgis | C36: North AA | D36: Account Management | E36: 45863 | F36: Migration suspense accounts | G36: 0 | H36: 0 | I36: 1 | J36: 0 | K36: 0 | L36: 0 | M36: 0 | N36: 225315.21 | O36: =G36+H36+I36+J36+K36+L36+M36-P36 -> 1 | P36: 0
A37: 31 | B37: Arada Giorgis | C37: North AA | D37: Account Management | F37: sundry debtors uncollected RTGS commission | G37: 0 | H37: 0 | I37: 0 | J37: 0 | K37: 0 | L37: 0 | M37: 1 | N37: 350 | O37: =G37+H37+I37+J37+K37+L37+M37-P37 -> 0 | P37: 1
A38: 32 | B38: Arada Giorgis | C38: North AA | D38: Account Management | E38: 45863 | F38: Sundry debtors - RECEIVABLE COURT CASE | G38: 0 | H38: 0 | I38: 0 | J38: 0 | K38: 0 | L38: 0 | M38: 1 | N38: 184 | O38: =G38+H38+I38+J38+K38+L38+M38-P38 -> 1 | P38: 0
A39: 33 | B39: Arada Giorgis | C39: North AA | D39: Account Management | E39: 45863 | F39: Sundry creditors(OFFICE RENT) | G39: 0 | H39: 0 | I39: 0 | J39: 0 | K39: 0 | L39: 0 | M39: 1 | N39: 3146426.2 | O39: =G39+H39+I39+J39+K39+L39+M39-P39 -> 1 | P39: 0
A40: 34 | B40: Arada Giorgis | C40: North AA | D40: Deposit Account | F40: Dormant accounts Found at the branch | G40: 0 | H40: 0 | I40: 0 | J40: 0 | K40: 259 | L40: 0 | M40: 0 | N40: 2597508 | O40: =G40+H40+I40+J40+K40+L40+M40-P40 -> 258 | P40: 1
...

Sheet South
B1: NIB International Bank S.C
B2: South AA District
B3: Monthly internal Control Reports
B4: As of July 31, 2026
A5: Ser. No | B5: Branch | C5: District | D5: Operation area | E5: ATM Cases | G5: It Case | H5: Zero Balance | I5: Dormant A/C | J5: Cheque Bok Case | K5: Other cases | L5: Posting Date | M5: Types of Irregularities/problems | N5: Amount involved in Birr | O5: Status of the irregularities
D6: Operation area | E6: Mismatch | F6: Long outstanding | K6: finding NO. | M6: Finding | O6: Unrectified | P6: Rectified | Q6: Unrectified In Amount
A7: 1 | B7: Africa Avenue | C7: South AA | D7: Cash and Cash Items | K7: 1 | N7: 579734 | O7: =E7+F7+G7+H7+I7+J7+K7 -> 1
A8: 2 | B8: Africa Avenue | C8: South AA | K8: 1 | M8: CASH sorting,counting and wrapping area of the branch were not separeted | N8: 0 | O8: =E8+F8+G8+H8+I8+J8+K8 -> 1
A9: 3 | B9: Africa Avenue | C9: South AA | D9: Account Management | M9: Absence of source documents. | O9: =E9+F9+G9+H9+I9+J9+K9 -> 0
A10: 4 | B10: Africa Avenue | C10: South AA | G10: 1 | M10: Total fixed asset | N10: -4394768.3 | O10: =E10+F10+G10+H10+I10+J10+K10 -> 1
A11: 5 | B11: Africa Avenue | C11: South AA | G11: 1 | M11: Inter branch T-24 R10 | N11: -6.1324863e+08 | O11: =E11+F11+G11+H11+I11+J11+K11 -> 1
A12: 6 | B12: Africa Avenue | C12: South AA | G12: 1 | M12: Migration suspense accounts | N12: 30607.14 | O12: =E12+F12+G12+H12+I12+J12+K12 -> 1
A13: 7 | B13: Africa Avenue | C13: South AA | G13: 1 | M13: Gain on A/L Revaluation | N13: 1175664.6 | O13: =E13+F13+G13+H13+I13+J13+K13 -> 1
A14: 8 | B14: Africa Avenue | C14: South AA | M14: Abnormal Balance | O14: =E14+F14+G14+H14+I14+J14+K14 -> 0
A15: 9 | B15: Africa Avenue | C15: South AA | G15: 1 | M15: Catch All - Unassigned PL | N15: 89957.59 | O15: =E15+F15+G15+H15+I15+J15+K15 -> 1
A16: 10 | B16: Africa Avenue | C16: South AA | G16: 1 | M16: DIFRERENCE IN NON-CONTINGENT | N16: 1500 | O16: =E16+F16+G16+H16+I16+J16+K16 -> 1
A17: 11 | B17: Africa Avenue | C17: South AA | M17: Long outstanding items. | O17: =E17+F17+G17+H17+I17+J17+K17 -> 0
A18: 12 | B18: Africa Avenue | C18: south AA | K18: 1 | M18: Sundry debtors :-accr interest Govt Bond & Dep | N18: -19221.55 | O18: =E18+F18+G18+H18+I18+J18+K18 -> 1
A19: 13 | B19: Africa Avenue | C19: South AA | K19: 1 | M19: Sundry debtors :-loan balance correction expense | N19: -9108.73 | O19: =E19+F19+G19+H19+I19+J19+K19 -> 1
A20: 14 | B20: Africa Avenue | C20: South AA | K20: 1 | M20: Sundry debtors :-Receivable from Atayol Asphalt | N20: -11887832 | O20: =E20+F20+G20+H20+I20+J20+K20 -> 1
A21: 15 | B21: Africa Avenue | C21: South AA | K21: 1 | M21: Sundry creditors:- loan balance correction income | N21: 43170.66 | O21: =E21+F21+G21+H21+I21+J21+K21 -> 1
A22: 16 | B22: Africa Avenue | C22: South AA | D22: Loan and Advances | K22: 3 | M22: Loan & Advances with Arrears:-BISRATA TAFA AND ISTANBUL TEXTILE PLC | N22: 19960881 | O22: =E22+F22+G22+H22+I22+J22+K22 -> 3
A23: 17 | B23: Africa Avenue | C23: South AA | D23: Deposit Accounts | H23: 35 | M23: Zero (0.00) balance Account Found at branch | N23: 0 | O23: =E23+F23+G23+H23+I23+J23+K23 -> 35
A24: 18 | B24: Africa Avenue | C24: South AA | I24: 2770 | M24: Dormant accounts Found at the branch | N24: 8148098.6 | O24: =E24+F24+G24+H24+I24+J24+K24 -> 2770
A25: 19 | B25: Africa Avenue | C25: South AA | D25: Fixed Asset Management | K25: 1 | M25: Defective/obsolete fixed assets found at the branch:- broken chair | N25: 0 | O25: =E25+F25+G25+H25+I25+J25+K25 -> 1
A26: 20 | B26: Africa Avenue | C26: South AA | D26: Card Banking | F26: 19 | M26: ATM cards & PIN mailers were not delivered to the respective account holders/ customers for a long period of time as presented below. ATM Card = 19 PIN Mailers = 11 | N26: 0 | O26: =E26+F26+G26+H26+I26+J26+K26 -> 19
A27: 21 | B27: Africa Avenue | C27: South AA | E27: 8 | M27: Mismatch Between ATM Card & Pin Mailers ATM Card =19 PIN Mailers = 12 | N27: 0 | O27: =E27+F27+G27+H27+I27+J27+K27 -> 8
A28: 22 | B28: Africa Avenue | C28: South AA | D28: Ticket Vouching | K28: 1 | L28: 46204 | M28: Fund Transfers were made without Customer's Signature:-DECHASSA WEYESSA TOLLA/7000021046758/ TO CBE | N28: 320000 | O28: =E28+F28+G28+H28+I28+J28+K28 -> 1
A29: 23 | B29: Africa Avenue | C29: South AA | K29: 1 | L29: 46204 | M29: Fund Transfers were made without Customer's Signature:- SEKET IMPORT AND EXPORT TRADING PLC /7000113962742/ TO CBE | N29: 2999700 | O29: =E29+F29+G29+H29+I29+J29+K29 -> 1
A30: 24 | B30: Africa Avenue | C30: South AA | K30: 1 | L30: 46206 | M30: Fund Transfers were made without Customer's Signature:-R AND M BUSINESS PLC /7000002626743/ TO AWASH BANK | N30: 250000 | O30: =E30+F30+G30+H30+I30+J30+K30 -> 1
A31: 25 | B31: Africa Avenue | C31: South AA | K31: 1 | L31: 46209 | M31: Fund Transfers were made without Customer's Signature:-R AND M BUSINESS PLC /7000002626743/ TO UNITED BANK | N31: 950000 | O31: =E31+F31+G31+H31+I31+J31+K31 -> 1
A32: 26 | B32: Africa Avenue | C32: South AA | K32: 1 | L32: 46217 | M32: Fund Transfers were made without Customer's Signature:- AMIR ZINABU TESSEMA/7000102473227/ TO CBE | N32: 100000 | O32: =E32+F32+G32+H32+I32+J32+K32 -> 1
A33: 27 | B33: Africa Avenue | C33: South AA | K33: 1 | L33: 46226 | M33: Fund Transfers were made without Customer's Signature:- ABIMELEK DANIEL BEKELE/7000053780534/ TO CBE | N33: 75000 | O33: =E33+F33+G33+H33+I33+J33+K33 -> 1
A34: 28 | B34: Africa Avenue | C34: South AA | K34: 1 | L34: 46232 | M34: Fund Transfers were made without Customer's Signature:- MULUKEN MOHAMMED AHMED/7000015183409/ TO ABISSINIYA BANK | N34: 77875 | O34: =E34+F34+G34+H34+I34+J34+K34 -> 1
A35: 29 | B35: AKAKI GEBEYA | C35: South AA | D35: Cash& cash items | K35: 1 | M35: Difference observed on ATM cash balance.(The physical cash count balance of ATM have shown a difference of Birr 14,300.00 Excess compared with the general ledger balance on July31, 2026 . ) | N35: 14300 | O35: =E35+F35+G35+H35+I35+J35+K35 -> 1
A36: 30 | B36: AKAKI GEBEYA | C36: South AA | M36: Absence of source documents. | O36: =E36+F36+G36+H36+I36+J36+K36 -> 0
A37: 31 | B37: AKAKI GEBEYA | C37: South AA | D37: Account Management | G37: 1 | M37: Total fixed asset | N37: -2004355.7 | O37: =E37+F37+G37+H37+I37+J37+K37 -> 1
A38: 32 | B38: AKAKI GEBEYA | C38: South AA | G38: 1 | M38: Inter branch T-24 R10 - | N38: -12308761 | O38: =E38+F38+G38+H38+I38+J38+K38 -> 1
A39: 33 | B39: AKAKI GEBEYA | C39: South AA | G39: 1 | M39: Migration suspense accounts | N39: 349.55 | O39: =E39+F39+G39+H39+I39+J39+K39 -> 1
A40: 34 | B40: AKAKI GEBEYA | C40: South AA | G40: 1 | M40: Gain on A/L revaluation | N40: 13342.17 | O40: =E40+F40+G40+H40+I40+J40+K40 -> 1
...

Sheet West
A1: NIB International Bank S.C
A2: West District
A3: Detailed Monthly internal Control Reports
A4: As of -July 31,2026
A5: SN | D5: Operation area | E5: ATM | G5: It | H5: Zero Balance | I5: Inactive/Dormant | J5: Ck book stock | K5: Other Cases | L5: Posting date | M5: Types of Irregularities/problems | N5: Amount involved in Birr | O5: Status of the irregularities
E6: Mismatch | F6: Long outstanding | N6: Amount involved | O6: Unrectified | P6: Rectified | Q6: Unrectified In Amount
B7: Branch | C7: District | D7: Operation area | K7: finding NO. | M7: Finding
A8: 1 | B8: Abdi Nono | C8: West | D8: Account Management | G8: 1 | M8: Total fixed asset | N8: -2279042.3 | O8: =E8+F8+G8+H8+I8+J8+K8-P8 -> 1
A9: 2 | B9: Abdi Nono | C9: West | G9: 1 | M9: Inter branch T-24 R10 | N9: -12136111 | O9: =E9+F9+G9+H9+I9+J9+K9-P9 -> 1
A10: 3 | B10: Abdi Nono | C10: West | K10: 1 | M10: Transfer from Tulu Jemo branch on date of 23/09/2025 w/ro Birhane Mekonnen accont number 7000018128147 until uncollected loan | N10: -39309.21 | O10: =E10+F10+G10+H10+I10+J10+K10-P10 -> 1
A11: 4 | B11: Abdi Nono | C11: West | H11: 6 | M11: Zero (0.00) balance Account Found at branch | O11: =E11+F11+G11+H11+I11+J11+K11-P11 -> 6
A12: 5 | B12: Abdi Nono | C12: West | I12: 1734 | M12: Dormant accounts Found at the branch | O12: =E12+F12+G12+H12+I12+J12+K12-P12 -> 1734
A13: 6 | B13: Abdi Nono | C13: West | D13: Card Banking | F13: 90 | M13: ATM cards & PIN mailers were not delivered to the respective account holders/ customers for a long period of time as presented below.ATM 90 PIN 28 | O13: =E13+F13+G13+H13+I13+J13+K13-P13 -> 90
A14: 7 | B14: Abdi Nono | C14: West | E14: 62 | M14: Mismatch of ATM and PIN | O14: =E14+F14+G14+H14+I14+J14+K14-P14 -> 62
A15: 8 | B15: Ambo | C15: West | D15: Cash and Cash Items | K15: 1 | M15: Difference observed on ATM cash balance.(The physical cash count252,350 balance of ATM have shown a difference of Birr 1,050 compared with the general ledger balance 253,400) | N15: 1050 | O15: =E15+F15+G15+H15+I15+J15+K15-P15 -> 1
A16: 9 | B16: Ambo | C16: West | D16: Account Management | G16: 1 | M16: Total fixed asset | N16: 947228.67 | O16: =E16+F16+G16+H16+I16+J16+K16-P16 -> 1
A17: 10 | B17: Ambo | C17: West | G17: 1 | M17: Inter branch T-24 R10 | N17: 9472903.1 | O17: =E17+F17+G17+H17+I17+J17+K17-P17 -> 1
A18: 11 | B18: Ambo | C18: West | G18: 1 | M18: Migration suspense accounts | N18: -1089.24 | O18: =E18+F18+G18+H18+I18+J18+K18-P18 -> 1
A19: 12 | B19: Ambo | C19: West | D19: Loan and Advances | K19: 1 | M19: Sundry debtors (Gemechu Defar ,date 09/04/2019EX staff fraud case) | N19: 120492.56 | O19: =E19+F19+G19+H19+I19+J19+K19-P19 -> 1
A20: 13 | B20: Ambo | C20: West | K20: 1 | M20: Loan under loss category Abebe Melese EX staff Emergancy loan | N20: 40334.98 | O20: =E20+F20+G20+H20+I20+J20+K20-P20 -> 1
A21: 14 | B21: Ambo | C21: West | D21: Deposit Accounts | I21: 4887 | M21: Dormant accounts Found at the branch | N21: 1348868.6 | O21: =E21+F21+G21+H21+I21+J21+K21-P21 -> 4887
A22: 15 | B22: Ambo | C22: West | D22: Fixed Asset Management | K22: 1 | M22: managerial swivel chair 1/2 lather tag number NIB/AMBOB/01/016 | O22: =E22+F22+G22+H22+I22+J22+K22-P22 -> 1
A23: 16 | B23: Ambo | C23: West | K23: 1 | M23: Cleriical swivel chair tag nuber AMBOOB/01/018 | O23: =E23+F23+G23+H23+I23+J23+K23-P23 -> 1
A24: 17 | B24: Ambo | C24: West | D24: Card Banking | F24: 229 | M24: ATM cards & PIN mailers were not delivered to the respective account holders/ customers for a long period of time as presented below.(ATM carde 229 & PIN 119 | O24: =E24+F24+G24+H24+I24+J24+K24-P24 -> 229
A25: 18 | B25: Ambo | C25: West | D25: Card Banking | E25: 110 | M25: Mismatch of ATM and PIN | O25: =E25+F25+G25+H25+I25+J25+K25-P25 -> 110
A26: 19 | B26: Alem Bank Tro | C26: West | D26: Account Management | G26: 1 | M26: Catch all asset & liabilty | N26: 10215 | O26: =E26+F26+G26+H26+I26+J26+K26-P26 -> 1
A27: 20 | B27: Alem Bank Tro | C27: West | G27: 1 | M27: Migration suspense accounts | N27: 0.27 | O27: =E27+F27+G27+H27+I27+J27+K27-P27 -> 1
A28: 21 | B28: Alem Bank Tro | C28: West | D28: Loan and Advances | K28: 1 | M28: MUSTEFA ABDELLA SHIFA STATUS SUB ARR-DAYS 160 EX staff Emergency loan | N28: 41659.8 | O28: =E28+F28+G28+H28+I28+J28+K28-P28 -> 1
A29: 22 | B29: Alem Bank Tro | C29: West | D29: Card Banking | F29: 123 | M29: ATM cards & PIN mailers were not delivered to the respective account holders/ customers for a long period of time as presented below.ATM 123 PIN 22 | O29: =E29+F29+G29+H29+I29+J29+K29-P29 -> 123
A30: 23 | B30: Alem Bank Tro | C30: West | D30: Card Banking | E30: 101 | M30: Mismatch of ATM and PIN | O30: =E30+F30+G30+H30+I30+J30+K30-P30 -> 101
A31: 24 | B31: Addisu Mikael | C31: West | D31: Cash and Cash Items | K31: 1 | M31: Cash in teller showed on GL but the cash is not found in our vault | N31: 10.01 | O31: =E31+F31+G31+H31+I31+J31+K31-P31 -> 1
A32: 25 | B32: Addisu Mikael | C32: West | K32: 1 | M32: Difference observed on ATM cash balance.(The physical cash count 283,800 balance of ATM have shown a difference of Birr 67,631.93 compared with the general ledger balance 216,168.07) | N32: 67631.93 | O32: =E32+F32+G32+H32+I32+J32+K32-P32 -> 1
A33: 26 | B33: Addisu Mikael | C33: West | G33: 1 | M33: Total fixed asset | N33: -2761532.5 | O33: =E33+F33+G33+H33+I33+J33+K33-P33 -> 1
A34: 27 | B34: Addisu Mikael | C34: West | G34: 1 | M34: Inter branch T-24 R10 | N34: -72826784 | O34: =E34+F34+G34+H34+I34+J34+K34-P34 -> 1
A35: 28 | B35: Addisu Mikael | C35: West | G35: 1 | M35: Migration suspense accounts | N35: 20.42 | O35: =E35+F35+G35+H35+I35+J35+K35-P35 -> 1
A36: 29 | B36: Addisu Mikael | C36: West | D36: Deposit Accounts | H36: 6 | M36: Zero (0.00) balance Account Found at branch | O36: =E36+F36+G36+H36+I36+J36+K36-P36 -> 6
A37: 30 | B37: Addisu Mikael | C37: West | I37: 1069 | M37: Dormant accounts Found at the branch | O37: =E37+F37+G37+H37+I37+J37+K37-P37 -> 1069
A38: 31 | B38: Addisu Mikael | C38: West | D38: Card Banking | F38: 264 | M38: ATM cards & PIN mailers were not delivered to the respective account holders/ customers for a long period of time as presented below.(ATM card 264 & PIN 234) | O38: =E38+F38+G38+H38+I38+J38+K38-P38 -> 264
A39: 32 | B39: Addisu Mikael | C39: West | D39: Card Banking | E39: 30 | M39: Mismatch of ATM and PIN | O39: =E39+F39+G39+H39+I39+J39+K39-P39 -> 30
A40: 33 | B40: Adarash | C40: West | D40: Account Management | G40: 1 | M40: Inter branch T-24 R10 | N40: -1912138266 | O40: =E40+F40+G40+H40+I40+J40+K40-P40 -> 1
...

Sheet Hawassa
A1: NIB International Bank S.C
A2: Hawassa District
A3: Detailed Monthly internal Control Reports
A4: As of JULY 31, 2026 | C4: as of march 31,2025
A5: SN | B5: Branch | C5: District | D5: Transaction date | E5: Operation Area | F5: Types of irregularities | G5: ATM Cases | I5: IT Case | J5: Zero balance | K5: Dormant A/c | L5: Cheque Bokk case | M5: Other Case | N5: Amount involved | O5: Status of the irregularities
G6: Mismatch | H6: Long outstanding | O6: Unrectified | P6: Rectified | Q6: Unrectified In Amount
A7: 1 | B7: Adola Woyu | C7: Hawassa | E7: Cash & Cash Item | F7: Difference observed on ATM cash balance.(The physical cash count balance of ATM have shown a difference of Birr compared with the general ledger balance . ) ATM GL - ATM THE PHYSICAL CASH --- | G7: 0 | H7: 0 | I7: 0 | J7: 0 | K7: 0 | L7: 0 | M7: 1 | N7: 21685.99 | O7: =G7+H7+I7+J7+K7+L7+M7 -> 1 | P7: 0 | Q7: 0
A8: 2 | B8: Adola Woyu | C8: Hawassa | E8: Deposit Account | F8: Dormant accounts Found at the branch | G8: 0 | H8: 0 | I8: 0 | J8: 0 | K8: 200 | L8: 0 | M8: 0 | N8: 25016.17 | O8: =G8+H8+I8+J8+K8+L8+M8 -> 200 | P8: 0 | Q8: 0
A9: 3 | B9: Adola Woyu | C9: Hawassa | E9: Ticket Vouching | F9: WITHDRAWAL done without cutomer signature | G9: 0 | H9: 0 | I9: 0 | J9: 0 | K9: 0 | L9: 0 | M9: 2 | N9: 60000 | O9: =G9+H9+I9+J9+K9+L9+M9 -> 2 | P9: 0 | Q9: 0
A10: 4 | B10: Adola Woyu | C10: Hawassa | E10: Ticket Vouching | F10: Transfer done without cutomer signature | G10: 0 | H10: 0 | I10: 0 | J10: 0 | K10: 0 | L10: 0 | M10: 3 | N10: 450000 | O10: =G10+H10+I10+J10+K10+L10+M10 -> 3 | P10: 0 | Q10: 0
A11: 5 | B11: Aleta Chuko | C11: Hawassa | E11: Deposit Account | F11: Dormant accounts Found at the branch | G11: 0 | H11: 0 | I11: 0 | J11: 0 | K11: 141 | L11: 0 | M11: 0 | N11: 70373.66 | O11: =G11+H11+I11+J11+K11+L11+M11 -> 141 | P11: 0 | Q11: 0
A12: 6 | B12: Aleta Chuko | C12: Hawassa | E12: Account Management | F12: GAIN on A/L Revaluation | G12: 0 | H12: 0 | I12: 1 | J12: 0 | K12: 0 | L12: 0 | M12: 0 | N12: 7757.41 | O12: =G12+H12+I12+J12+K12+L12+M12 -> 1 | P12: 0 | Q12: 0
A13: 7 | B13: Aleta Chuko | C13: Hawassa | E13: Account Management | F13: Catch all asset and liability | G13: 0 | H13: 0 | I13: 1 | J13: 0 | K13: 0 | L13: 0 | M13: 0 | N13: 10184.84 | O13: =G13+H13+I13+J13+K13+L13+M13 -> 1 | P13: 0 | Q13: 0
A14: 8 | B14: Aleta Chuko | C14: Hawassa | E14: Card Banking | F14: ATM cards & PIN mailers were not delivered to the respective account holders/ customers for a long period of time as presented below. | G14: 0 | H14: 736 | I14: 0 | J14: 0 | K14: 0 | L14: 0 | M14: 0 | N14: 36800 | O14: =G14+H14+I14+J14+K14+L14+M14 -> 736 | P14: 0 | Q14: 0
A15: 9 | B15: Aleta Chuko | C15: Hawassa | E15: Card Banking | F15: Mismatch Between ATM Card & Pinmailers | G15: 160 | H15: 0 | O15: =G15+H15+I15+J15+K15+L15+M15 -> 160
A16: 10 | B16: Aleta Chuko | C16: Hawassa | E16: Ticket Vouching | F16: Cash Withdrawal done without cutomer signature | G16: 0 | H16: 0 | I16: 0 | J16: 0 | K16: 0 | L16: 0 | M16: 4 | N16: 160000 | O16: =G16+H16+I16+J16+K16+L16+M16 -> 4 | P16: 0 | Q16: 0
A17: 11 | B17: Aleta Chuko | C17: Hawassa | D17: JULY 15,17,20,23,24,26,27,28,29 2026 | E17: Ticket Vouching | F17: Transfer done without cutomer signature | G17: 0 | H17: 0 | I17: 0 | J17: 0 | K17: 0 | L17: 0 | M17: 15 | N17: 1978200 | O17: =G17+H17+I17+J17+K17+L17+M17 -> 15 | P17: 0 | Q17: 0
A18: 12 | B18: Aleta Wondo | C18: Hawassa | D18: 31/07/2026 | E18: Cash & Cash Item | F18: Difference observed on ATM cash balance.(The physical cash count balance of ATM have shown a difference of Birr compared with the general ledger balance . ) ATM GL - ATM THE PHYSICAL CASH --- | G18: 0 | H18: 0 | I18: 0 | J18: 0 | K18: 0 | L18: 0 | M18: 1 | N18: 5085.48 | O18: =G18+H18+I18+J18+K18+L18+M18 -> 1 | P18: 0 | Q18: 0
A19: 13 | B19: Aleta Wondo | C19: Hawassa | E19: Account Management | F19: Inter branch T-24 R10 | G19: 0 | H19: 0 | I19: 1 | J19: 0 | K19: 0 | L19: 0 | M19: 0 | N19: 27764690 | O19: =G19+H19+I19+J19+K19+L19+M19 -> 1 | P19: 0 | Q19: 0
A20: 14 | B20: Aleta Wondo | C20: Hawassa | E20: Account Management | F20: Migration suspense accounts | G20: 0 | H20: 0 | I20: 1 | J20: 0 | K20: 0 | L20: 0 | M20: 0 | N20: 6814.44 | O20: =G20+H20+I20+J20+K20+L20+M20 -> 1 | P20: 0 | Q20: 0
A21: 15 | B21: Aleta Wondo | C21: Hawassa | E21: Loan & Advance | F21: Arrears inconnection With loan collection | G21: 0 | H21: 0 | I21: 0 | J21: 0 | K21: 0 | L21: 0 | M21: 4 | N21: 763377.31 | O21: =G21+H21+I21+J21+K21+L21+M21 -> 4 | P21: 0 | Q21: 0
A22: 16 | B22: Aleta Wondo | C22: Hawassa | E22: Deposit Account | F22: Dormant accounts Found at the branch | G22: 0 | H22: 0 | I22: 0 | J22: 0 | K22: 351 | L22: 0 | M22: 0 | N22: 1655888.1 | O22: =G22+H22+I22+J22+K22+L22+M22 -> 351 | P22: 0 | Q22: 0
A23: 17 | B23: Aleta Wondo | C23: Hawassa | E23: Account Management | F23: GAIN on A/L Revaluation | G23: 0 | H23: 0 | I23: 1 | J23: 0 | K23: 0 | L23: 0 | M23: 0 | N23: 64829.81 | O23: =G23+H23+I23+J23+K23+L23+M23 -> 1 | P23: 0 | Q23: 0
A24: 18 | B24: Aleta Wondo | C24: Hawassa | E24: Account Management | F24: Catch all asset and liability | G24: 0 | H24: 0 | I24: 1 | J24: 0 | K24: 0 | L24: 0 | M24: 0 | N24: 6824.06 | O24: =G24+H24+I24+J24+K24+L24+M24 -> 1 | P24: 0 | Q24: 0
A25: 19 | B25: Aleta Wondo | C25: Hawassa | E25: Card Banking | F25: ATM cards & PIN mailers were not delivered to the respective account holders/ customers for a long period of time as presented below. Pin 1383 card 1439 | G25: 0 | H25: 1439 | I25: 0 | J25: 0 | K25: 0 | L25: 0 | M25: 0 | N25: 71950 | O25: =G25+H25+I25+J25+K25+L25+M25 -> 1439 | P25: 0 | Q25: 0
A26: 20 | B26: Aleta Wondo | C26: Hawassa | E26: Card Banking | F26: Mismatch Between ATM Card & Pinmailers | G26: =1439-1383 -> 56 | H26: 0 | I26: 0 | J26: 0 | K26: 0 | L26: 0 | M26: 0 | N26: 0 | O26: =G26+H26+I26+J26+K26+L26+M26 -> 56
A27: 21 | B27: Aleta Wondo | C27: Hawassa | E27: Negotiable Instrument | F27: Cheque books prepared but not delivered to customers for a long period of time. | G27: 0 | H27: 0 | I27: 0 | J27: 0 | K27: 0 | L27: 1 | M27: 0 | N27: 100 | O27: =G27+H27+I27+J27+K27+L27+M27 -> 1 | P27: 0 | Q27: 0
A28: 22 | B28: Aleta Wondo | C28: Hawassa | E28: Account Management | F28: Legacy inter branch account | G28: 0 | H28: 0 | I28: 1 | J28: 0 | K28: 0 | L28: 0 | M28: 0 | N28: 379025.3 | O28: =G28+H28+I28+J28+K28+L28+M28 -> 1 | P28: 0 | Q28: 0
A29: 23 | B29: Aleta Wondo | C29: Hawassa | E29: Account Management | F29: Difference in non contigent | G29: 0 | H29: 0 | I29: 1 | J29: 0 | K29: 0 | L29: 0 | M29: 0 | N29: 21.5 | O29: =G29+H29+I29+J29+K29+L29+M29 -> 1 | P29: 0 | Q29: 0
A30: 24 | B30: Aleta Wondo | C30: Hawassa | E30: Ticket Vouching | F30: Transfer done without cutomer signature | G30: 0 | H30: 0 | I30: 0 | J30: 0 | K30: 0 | L30: 0 | M30: 3 | N30: 821000 | O30: =G30+H30+I30+J30+K30+L30+M30 -> 3 | P30: 0 | Q30: 0
A31: 25 | B31: Arba Minch | C31: Hawassa | D31: 28-2-2028 | E31: Account Management | F31: Migration suspense accounts | G31: 0 | H31: 0 | I31: 1 | J31: 0 | K31: 0 | L31: 0 | N31: 9335.29 | O31: =G31+H31+I31+J31+K31+L31+M31 -> 1 | P31: 0 | Q31: 0
A32: 26 | B32: Arba Minch | C32: Hawassa | E32: Loan & Advance | F32: Arrears inconnection with loan collection | G32: 0 | H32: 0 | J32: 0 | K32: 0 | L32: 0 | M32: 5 | N32: 1201162.6 | O32: =G32+H32+I32+J32+K32+L32+M32 -> 5 | P32: 0 | Q32: 0
A33: 27 | B33: Arba Minch | C33: Hawassa | D33: 28-2-2026 | E33: Deposit Account | F33: Zero (0.00) balance Account Found at branch | G33: 0 | H33: 0 | I33: 0 | J33: 5 | K33: 0 | L33: 0 | M33: 0 | N33: 0 | O33: =G33+H33+I33+J33+K33+L33+M33 -> 5 | P33: 0 | Q33: 0
A34: 28 | B34: Arba Minch | C34: Hawassa | D34: 28-02-2026 | E34: Card Banking | F34: ATM cards & PIN mailers were not delivered to the respective account holders/ customers for a long period of time as presented below. | G34: 0 | H34: 3109 | I34: 0 | J34: 0 | K34: 0 | L34: 0 | M34: 0 | N34: 155450 | O34: =G34+H34+I34+J34+K34+L34+M34 -> 3109 | P34: 0 | Q34: 0
A35: 29 | B35: Arba Minch | C35: Hawassa | D35: 28-2-2026 | E35: Account Management | F35: Legacy inter branch account | G35: 0 | H35: 0 | I35: 1 | J35: 0 | K35: 0 | L35: 0 | M35: 0 | N35: 674393.07 | O35: =G35+H35+I35+J35+K35+L35+M35 -> 1 | P35: 0 | Q35: 0
A36: 30 | B36: Arba Minch | C36: Hawassa | D36: 21&25&21/7/2026 | E36: Ticket Vouching | F36: Transfer done without cutomer signature | G36: 0 | H36: 0 | I36: 0 | J36: 0 | K36: 0 | L36: 0 | M36: 3 | N36: 605650 | O36: =G36+H36+I36+J36+K36+L36+M36 -> 3 | P36: 0 | Q36: 0
A37: 31 | B37: Arba Minch | C37: Hawassa | D37: 21/7/26 | E37: Ticket Vouching | F37: cash withdrawal done with out customer signature | G37: 0 | H37: 0 | I37: 0 | J37: 0 | K37: 0 | L37: 0 | M37: 1 | N37: 50000 | O37: =G37+H37+I37+J37+K37+L37+M37 -> 1 | P37: 0 | Q37: 0
A38: 32 | B38: Arba Minch | C38: Hawassa | D38: 31/07/2026 | E38: Account Management | F38: Sundry creditors:long outstanding inconnection with LMTS | G38: 0 | H38: 0 | I38: 0 | J38: 0 | K38: 0 | L38: 0 | M38: 1 | N38: 1000 | O38: =G38+H38+I38+J38+K38+L38+M38 -> 1 | P38: 0 | Q38: 0
A39: 33 | B39: Arba Minch | C39: Hawassa | D39: 46241 | E39: Cash & Cash Item | F39: Cash Shortage Report | G39: 0 | H39: 0 | I39: 0 | J39: 0 | K39: 0 | L39: 0 | M39: 1 | N39: 900 | O39: =G39+H39+I39+J39+K39+L39+M39 -> 1 | P39: 0 | Q39: 0
A40: 34 | B40: Arba Minch Gebeya | C40: Hawassa | E40: Cash & Cash Item | F40: Difference observed on ATM cash balance.(The physical cash count balance of ATM 87,800 have shown a difference of Birr 56,831.61 compared with the general ledger balance OF 30,968.39 | G40: 0 | H40: 0 | I40: 0 | J40: 0 | K40: 0 | L40: 0 | M40: 1 | N40: 56831.61 | O40: =G40+H40+I40+J40+K40+L40+M40 -> 1 | P40: 0 | Q40: 0
...

Sheet B-Dar
A1: NIB International Bank S.C
A2: Name of Departments/NAAD
A3: Detailed Monthly internal Control Reports
A4: As of JULY 31 2026 month report | C4: as of march 31,2025
A5: SN | B5: Branch | C5: District | E5: Types of irregularities | F5: ATM Cases | L5: Other Case No. | M5: Amount involved | N5: Status of the irregularities
D6: Transaction Date | F6: Mismatch | G6: Long O/S | H6: IT Cases | I6: Zero Bal. | J6: Dormant A/C | K6: CK Book stock | N6: Unrectified | O6: Rectified | P6: Unrectified In Amount
A7: 1 | B7: Debre Tabor | C7: Bahir Dar | D7: Various Date | E7: Dormant accounts found at the branch | F7: 0 | G7: 0 | H7: 0 | I7: 0 | J7: 122 | K7: 0 | L7: 0 | M7: 26996.52 | N7: =F7+G7+H7+I7+J7+K7+L7-O7 -> 0 | O7: 122 | P7: 122
A8: 2 | B8: Debre Tabor | C8: Bahir Dar | D8: Various Date | E8: Absence of FCY License | F8: 0 | G8: 0 | H8: 0 | I8: 0 | J8: 0 | K8: 0 | L8: 1 | M8: 0 | N8: =F8+G8+H8+I8+J8+K8+L8-O8 -> 1
A9: 3 | B9: Debre Tabor | C9: Bahir Dar | D9: Various Date | E9: Defective/Obsolete fixed assets found at the branch (note counter machine & casio calculator) | F9: 0 | G9: 0 | H9: 0 | I9: 0 | J9: 0 | K9: 0 | L9: 4 | M9: 60383.93 | N9: =F9+G9+H9+I9+J9+K9+L9-O9 -> 4
A10: 4 | B10: Debre Tabor | C10: Bahir Dar | D10: Various Date | E10: ATM cards were not delivered to the respective account holders for a long period of time | F10: 0 | G10: 85 | H10: 0 | I10: 0 | J10: 0 | K10: 0 | L10: 0 | M10: 7391.6 | N10: =F10+G10+H10+I10+J10+K10+L10-O10 -> 85
A11: 5 | B11: Debre Tabor | C11: Bahir Dar | D11: Various Date | E11: ATM cards and PIN Difference | F11: 54 | G11: 0 | H11: 0 | I11: 0 | J11: 0 | K11: 0 | L11: 0 | M11: 0 | N11: =F11+G11+H11+I11+J11+K11+L11-O11 -> 54
A12: 6 | B12: Nifas Mewucha | C12: Bahir Dar | D12: branch oppening | E12: Absence of FCY license | F12: 0 | G12: 0 | H12: 0 | I12: 0 | J12: 0 | K12: 0 | L12: 1 | M12: 0 | N12: =F12+G12+H12+I12+J12+K12+L12-O12 -> 1
A13: 7 | B13: Nifas Mewucha | C13: Bahir Dar | D13: Dormat account | E13: Dormant accounts Found at the branch | F13: 0 | G13: 0 | H13: 0 | I13: 0 | J13: 31 | K13: 0 | L13: 0 | M13: 4769.01 | N13: =F13+G13+H13+I13+J13+K13+L13-O13 -> 0 | O13: 31 | P13: 31
A14: 8 | B14: Nifas Mewucha | C14: Bahir Dar | D14: various | E14: ATM cards & PIN mailers were not delivered to the respective account holders/ customers for a long period of time as presented below. | F14: 0 | G14: 11 | H14: 0 | I14: 0 | J14: 0 | K14: 0 | L14: 0 | M14: 1100 | N14: =F14+G14+H14+I14+J14+K14+L14-O14 -> 11
