Workbook

Sheet Summary July 25-August 24
A1: SUMMARIZED IRREGULARITIES
A2: As at July 2025
A3: SN | B3: Total No. of Branches | C3: District | D3: Others Cases | E3: Status of the irregularities
E4: Unrectified | F4: Rectified | G4: rectified percetage
B5: A | C5: B | D5: D | E5: E | F5: F | G5: G
A6: 1 | B6: 20 | C6: Jimma | D6: 5 | F6: 5 | G6: =F6/D6 -> 1
A7: 2 | B7: 7 | C7: Mekelle | D7: 89 | E7: =D7-F7 -> 1 | F7: 88 | G7: =F7/D7 -> 0.98876404
A8: 3 | B8: 42 | C8: North | D8: 210 | E8: =D8-F8 -> 2 | F8: 208 | G8: =F8/D8 -> 0.99047619
A9: 4 | B9: 49 | C9: East | D9: 1302 | E9: =D9-F9 -> 4 | F9: 1298 | G9: =F9/D9 -> 0.9969278
A10: 5 | B10: 36 | C10: Hossaena | D10: 85 | E10: =D10-F10 -> 2 | F10: 83 | G10: =F10/D10 -> 0.97647059
A11: 6 | B11: 26 | C11: Wolkite | D11: 41 | E11: =D11-F11 -> 0 | F11: 41 | G11: =F11/D11 -> 1
A12: 7 | B12: 33 | C12: Adama | D12: 160 | E12: =D12-F12 -> 0 | F12: 160 | G12: =F12/D12 -> 1
A13: 8 | B13: 52 | C13: South | D13: 401 | E13: =D13-F13 -> 2 | F13: 399 | G13: =F13/D13 -> 0.99501247
A14: 9 | B14: 17 | C14: DIREDAWA | D14: 352 | E14: =D14-F14 -> 0 | F14: 352 | G14: =F14/D14 -> 1
A15: 10 | B15: 57 | C15: West | D15: 187 | E15: =D15-F15 -> 0 | F15: 187 | G15: =F15/D15 -> 1
A16: 11 | B16: 25 | C16: Bahi Dar | D16: 292 | E16: =D16-F16 -> 0 | F16: 292 | G16: =F16/D16 -> 1
A17: 12 | B17: 39 | C17: Hawassa | D17: 359 | E17: =D17-F17 -> 12 | F17: 347 | G17: =F17/D17 -> 0.96657382
A18: 13 | B18: 11 | C18: Dessie | D18: 56 | E18: =D18-F18 -> 12 | F18: 44 | G18: =F18/D18 -> 0.78571429
B19: =SUM(B6:B18) -> 414 | C19: TOTAL | D19: =SUM(D6:D18) -> 3539 | E19: =SUM(E6:E18) -> 35 | F19: =SUM(F6:F18) -> 3504 | G19: =F19/D19 -> 0.9901102
F20: =F19/D19 -> 0.9901102
A21: As at August 312025
A22: SN | B22: Total No. of Branches | C22: District | D22: Others Cases | E22: Status of the irregularities
E23: Unrectified | F23: Rectified | G23: rectified percetage
B24: A | C24: B | D24: D | E24: E | F24: F | G24: G
A25: 1 | B25: 20 | C25: Jimma | D25: 14 | E25: =D25-F25 -> 0 | F25: 14 | G25: =F25/D25 -> 1
A26: 2 | B26: 42 | C26: North | D26: 213 | E26: =D26-F26 -> 1 | F26: 212 | G26: =F26/D26 -> 0.99530516 | I26: 44
A27: 3 | B27: 57 | C27: West | D27: 593 | E27: =D27-F27 -> 5 | F27: 588 | G27: =F27/D27 -> 0.9915683
A28: 4 | B28: 49 | C28: East | D28: 1596 | E28: =D28-F28 -> 3 | F28: 1593 | G28: =F28/D28 -> 0.9981203
A29: 5 | B29: 17 | C29: DIREDAWA | D29: 818 | E29: =D29-F29 -> 0 | F29: 818 | G29: =F29/D29 -> 1
A30: 6 | B30: 33 | C30: Adama | D30: 230 | E30: =D30-F30 -> 0 | F30: 230 | G30: =F30/D30 -> 1
A31: 7 | B31: 52 | C31: South | D31: 1344 | E31: =D31-F31 -> 1 | F31: 1343 | G31: =F31/D31 -> 0.99925595
A32: 8 | B32: 36 | C32: Hossaena | D32: 231 | E32: =D32-F32 -> 0 | F32: 231 | G32: =F32/D32 -> 1
A33: 9 | B33: 26 | C33: Wolkite | D33: 83 | E33: =D33-F33 -> 0 | F33: 83 | G33: =F33/D33 -> 1
A34: 10 | B34: 7 | C34: Mekelle | D34: 30 | E34: =D34-F34 -> 0 | F34: 30 | G34: =F34/D34 -> 1
A35: 11 | B35: 39 | C35: Hawassa | D35: 395 | E35: =D35-F35 -> 17 | F35: 378 | G35: =F35/D35 -> 0.95696203
A36: 12 | B36: 11 | C36: Dessie | D36: 79 | E36: =D36-F36 -> 10 | F36: 69 | G36: =F36/D36 -> 0.87341772
A37: 13 | B37: 25 | C37: Bahi Dar | D37: 513 | E37: =D37-F37 -> 0 | F37: 513 | G37: =F37/D37 -> 1
B38: =SUM(B25:B37) -> 414 | C38: TOTAL | D38: =SUM(D25:D37) -> 6139 | E38: =SUM(E25:E37) -> 37 | F38: =SUM(F25:F37) -> 6102 | G38: =F38/D38 -> 0.99397296
F39: =F38/D38 -> 0.99397296
A40: As at September 2025
...

Sheet Detail monthly summaryBD
A2: ENTIRE SUMMARIZED IRREGULARITIES AS AT August 24,2026
A3: SN | B3: District | D3: Others Cases | E3: Status of the irregularities
C4: Month | E4: Unrectified | F4: Rectified | G4: rectified percetage
B5: A | C5: B | D5: C | E5: D | F5: F | G5: G
A6: 1 | B6: Adama | C6: July,2025 | D6: ='Summary July 25-August 24'!D12 -> 160 | E6: =D6-F6 -> 0 | F6: ='Summary July 25-August 24'!F12 -> 160 | G6: =F6/D6 -> 1
A7: 2 | B7: Adama | C7: August,2025 | D7: ='Summary July 25-August 24'!D30 -> 230 | E7: =D7-F7 -> 0 | F7: ='Summary July 25-August 24'!F30 -> 230 | G7: =F7/D7 -> 1
A8: 3 | B8: Adama | C8: September,2025 | D8: ='Summary July 25-August 24'!D51 -> 1731 | E8: =D8-F8 -> 0 | F8: ='Summary July 25-August 24'!F51 -> 1731 | G8: =F8/D8 -> 1
A9: 4 | B9: Adama | C9: October,2025 | D9: ='Summary July 25-August 24'!D67 -> 2584 | E9: =D9-F9 -> 0 | F9: ='Summary July 25-August 24'!F67 -> 2584 | G9: =F9/D9 -> 1
A10: 5 | B10: Adama | C10: November,2025 | D10: ='Summary July 25-August 24'!D86 -> 235 | E10: =D10-F10 -> 0 | F10: ='Summary July 25-August 24'!F86 -> 235 | G10: =F10/D10 -> 1
A11: 6 | B11: Adama | C11: December,2025 | D11: ='Summary July 25-August 24'!D105 -> 126 | E11: =D11-F11 -> 0 | F11: ='Summary July 25-August 24'!F105 -> 126 | G11: =F11/D11 -> 1
A12: 7 | B12: Adama | C12: January,2026 | D12: ='Summary July 25-August 24'!D124 -> 1497 | E12: =D12-F12 -> 0 | F12: ='Summary July 25-August 24'!F124 -> 1497 | G12: =F12/D12 -> 1
A13: 8 | B13: Adama | C13: February,2026 | D13: ='Summary July 25-August 24'!D143 -> 127 | E13: =D13-F13 -> 0 | F13: ='Summary July 25-August 24'!F143 -> 127 | G13: =F13/D13 -> 1
A14: 9 | B14: Adama | C14: March,2026 | D14: ='Summary July 25-August 24'!D162 -> 69 | E14: =D14-F14 -> 0 | F14: ='Summary July 25-August 24'!F162 -> 69 | G14: =F14/D14 -> 1
A15: 10 | B15: Adama | C15: April,2026 | D15: ='Summary July 25-August 24'!D182 -> 167 | E15: =D15-F15 -> 0 | F15: ='Summary July 25-August 24'!F182 -> 167 | G15: =F15/D15 -> 1
A16: 11 | B16: Adama | C16: May,2026 | D16: ='Summary July 25-August 24'!D204 -> 100 | E16: =D16-F16 -> 0 | F16: ='Summary July 25-August 24'!F204 -> 100 | G16: =F16/D16 -> 1
A17: 12 | B17: Adama | C17: June,2026 | D17: ='Summary July 25-August 24'!J226 -> 54 | E17: =D17-F17 -> 23 | F17: ='Summary July 25-August 24'!M226 -> 31 | G17: =F17/D17 -> 0.57407407
A18: 13 | B18: Adama | C18: July,2026 | D18: ='Summary July 25-August 24'!J246 -> 207 | E18: =D18-F18 -> 187 | F18: ='Summary July 25-August 24'!M246 -> 20 | G18: =F18/D18 -> 0.096618357
A19: 14 | B19: Adama | C19: Various internal Audit report | E19: =D19-F19 -> 0
D20: =SUM(D6:D19) -> 7287 | E20: =SUM(E6:E19) -> 210 | F20: =SUM(F6:F19) -> 7077 | G20: =F20/D20 -> 0.97118156
A21: 1 | B21: Bahi Dar | C21: July,2025 | D21: ='Summary July 25-August 24'!D16 -> 292 | E21: =D21-F21 -> 0 | F21: ='Summary July 25-August 24'!F16 -> 292 | G21: =F21/D21 -> 1
A22: 2 | B22: Bahi Dar | C22: August,2025 | D22: ='Summary July 25-August 24'!D37 -> 513 | E22: =D22-F22 -> 0 | F22: ='Summary July 25-August 24'!F37 -> 513 | G22: =F22/D22 -> 1
A23: 3 | B23: Bahi Dar | C23: September,2025 | D23: ='Summary July 25-August 24'!D55 -> 10510 | E23: =D23-F23 -> 0 | F23: ='Summary July 25-August 24'!F55 -> 10510 | G23: =F23/D23 -> 1
A24: 4 | B24: Bahi Dar | C24: October,2025 | D24: ='Summary July 25-August 24'!D68 -> 4589 | E24: =D24-F24 -> 54 | F24: ='Summary July 25-August 24'!F68 -> 4535 | G24: =F24/D24 -> 0.98823273
A25: 5 | B25: Bahi Dar | C25: November,2025 | D25: ='Summary July 25-August 24'!D87 -> 3650 | E25: =D25-F25 -> 16 | F25: ='Summary July 25-August 24'!F87 -> 3634 | G25: =F25/D25 -> 0.99561644
A26: 6 | B26: Bahi Dar | C26: December,2025 | D26: ='Summary July 25-August 24'!D106 -> 811 | E26: =D26-F26 -> 27 | F26: ='Summary July 25-August 24'!F106 -> 784 | G26: =F26/D26 -> 0.96670777
A27: 7 | B27: Bahi Dar | C27: January,2026 | D27: ='Summary July 25-August 24'!D125 -> 1334 | E27: =D27-F27 -> 30 | F27: ='Summary July 25-August 24'!F125 -> 1304 | G27: =F27/D27 -> 0.97751124
A28: 8 | B28: Bahi Dar | C28: February,2026 | D28: ='Summary July 25-August 24'!D144 -> 850 | E28: =D28-F28 -> 41 | F28: ='Summary July 25-August 24'!F144 -> 809 | G28: =F28/D28 -> 0.95176471
A29: 9 | B29: Bahi Dar | C29: March,2026 | D29: ='Summary July 25-August 24'!D163 -> 4249 | E29: =D29-F29 -> 32 | F29: ='Summary July 25-August 24'!F163 -> 4217 | G29: =F29/D29 -> 0.99246882
A30: 10 | B30: Bahi Dar | C30: April,2026 | D30: ='Summary July 25-August 24'!D183 -> 5197 | E30: =D30-F30 -> 25 | F30: ='Summary July 25-August 24'!F183 -> 5172 | G30: =F30/D30 -> 0.99518953
A31: 11 | B31: Bahi Dar | C31: May,2026 | D31: ='Summary July 25-August 24'!D205 -> 4292 | E31: =D31-F31 -> 95 | F31: ='Summary July 25-August 24'!F205 -> 4197 | G31: =F31/D31 -> 0.9778658
A32: 12 | B32: Bahi Dar | C32: June,2026 | D32: ='Summary July 25-August 24'!J227 -> 3734 | E32: =D32-F32 -> 36 | F32: ='Summary July 25-August 24'!M227 -> 3698 | G32: =F32/D32 -> 0.99035886
A33: 13 | B33: Bahi Dar | C33: July,2026 | D33: ='Summary July 25-August 24'!J247 -> 4342 | E33: =D33-F33 -> 4090 | F33: ='Summary July 25-August 24'!M247 -> 252 | G33: =F33/D33 -> 0.058037771
A34: 14 | B34: Bahi Dar | C34: Various internal Audit report | E34: =D34-F34 -> 0
D35: =SUM(D21:D34) -> 44363 | E35: =SUM(E21:E34) -> 4446 | F35: =SUM(F21:F34) -> 39917 | G35: =F35/D35 -> 0.89978135
A36: 1 | B36: Dessie | C36: July,2025 | D36: ='Summary July 25-August 24'!D18 -> 56 | E36: =D36-F36 -> 12 | F36: ='Summary July 25-August 24'!F18 -> 44 | G36: =F36/D36 -> 0.78571429
A37: 2 | B37: Dessie | C37: August,2025 | D37: ='Summary July 25-August 24'!D36 -> 79 | E37: =D37-F37 -> 10 | F37: ='Summary July 25-August 24'!F36 -> 69 | G37: =F37/D37 -> 0.87341772
A38: 3 | B38: Dessie | C38: September,2025 | D38: ='Summary July 25-August 24'!D56 -> 220 | E38: =D38-F38 -> 8 | F38: ='Summary July 25-August 24'!F56 -> 212 | G38: =F38/D38 -> 0.96363636
A39: 4 | B39: Dessie | C39: October,2025 | D39: ='Summary July 25-August 24'!D69 -> 100 | E39: =D39-F39 -> 5 | F39: ='Summary July 25-August 24'!F69 -> 95 | G39: =F39/D39 -> 0.95
A40: 5 | B40: Dessie | C40: November,2025 | D40: ='Summary July 25-August 24'!D88 -> 100 | E40: =D40-F40 -> 4 | F40: ='Summary July 25-August 24'!F88 -> 96 | G40: =F40/D40 -> 0.96
A41: 6 | B41: Dessie | C41: December,2025 | D41: ='Summary July 25-August 24'!D107 -> 44 | E41: =D41-F41 -> 13 | F41: ='Summary July 25-August 24'!F107 -> 31 | G41: =F41/D41 -> 0.70454545
...

Sheet Rank in other cases
A1: INTERNAL CONTROL DIVISION
A2: PERFORMANCE REPORT ON RECTIFICATION OF THE ENTIRE IRREGULARITIES FROM JULY,2025 UP TO August 24,2026
A3: SN | B3: Total No. of Branches | C3: District | D3: Total Others Cases(July 2025-February 2026 | F3: Status of the irregularities | I3: Remark
F4: Total outstanding unrectified cases | G4: Rectified | H4: Rank
B5: A | C5: B | D5: Unrectified | E5: Rectified | F5: F | G5: G | H5: I
A6: 1 | B6: 36 | C6: Hossaena | D6: ='Detail monthly summaryBD'!D110 -> 8258 | E6: ='Detail monthly summaryBD'!F110 -> 8168 | F6: =D6-G6 -> 90 | G6: =E6 -> 8168 | H6: =E6/D6 -> 0.98910148
A7: 2 | B7: 26 | C7: Wolkite | D7: ='Detail monthly summaryBD'!D200 -> 4666 | E7: ='Detail monthly summaryBD'!F200 -> 4550 | F7: =D7-G7 -> 116 | G7: =E7 -> 4550 | H7: =E7/D7 -> 0.97513931 | K7: =K5-K6 -> 0
A8: 3 | B8: 33 | C8: Adama | D8: ='Detail monthly summaryBD'!D20 -> 7287 | E8: ='Detail monthly summaryBD'!F20 -> 7077 | F8: =D8-G8 -> 210 | G8: =E8 -> 7077 | H8: =E8/D8 -> 0.97118156
A9: 4 | B9: 49 | C9: East | D9: ='Detail monthly summaryBD'!D80 -> 11464 | E9: ='Detail monthly summaryBD'!F80 -> 10792 | F9: =D9-G9 -> 672 | G9: =E9 -> 10792 | H9: =E9/D9 -> 0.94138172
A10: 5 | B10: 57 | C10: West | D10: ='Detail monthly summaryBD'!D185 -> 4823 | E10: ='Detail monthly summaryBD'!F185 -> 4467 | F10: =D10-G10 -> 356 | G10: =E10 -> 4467 | H10: =E10/D10 -> 0.92618702
A11: 6 | B11: 7 | C11: Mekelle | D11: ='Detail monthly summaryBD'!D140 -> 564 | E11: ='Detail monthly summaryBD'!F140 -> 514 | F11: =D11-G11 -> 50 | G11: =E11 -> 514 | H11: =E11/D11 -> 0.91134752
A12: 7 | B12: 42 | C12: North | D12: ='Detail monthly summaryBD'!D155 -> 5042 | E12: ='Detail monthly summaryBD'!F155 -> 4583 | F12: =D12-G12 -> 459 | G12: =E12 -> 4583 | H12: =E12/D12 -> 0.9089647
A13: 8 | B13: 25 | C13: Bahi Dar | D13: ='Detail monthly summaryBD'!D35 -> 44363 | E13: ='Detail monthly summaryBD'!F35 -> 39917 | F13: =D13-G13 -> 4446 | G13: =E13 -> 39917 | H13: =E13/D13 -> 0.89978135
A14: 9 | B14: 39 | C14: Hawassa | D14: ='Detail monthly summaryBD'!D95 -> 12817 | E14: ='Detail monthly summaryBD'!F95 -> 11339 | F14: =D14-G14 -> 1478 | G14: =E14 -> 11339 | H14: =E14/D14 -> 0.8846844
A15: 10 | B15: 17 | C15: DIREDAWA | D15: ='Detail monthly summaryBD'!D65 -> 5223 | E15: ='Detail monthly summaryBD'!F65 -> 4274 | F15: =D15-G15 -> 949 | G15: =E15 -> 4274 | H15: =E15/D15 -> 0.81830366
A16: 11 | B16: 58 | C16: South | D16: ='Detail monthly summaryBD'!D170 -> 17123 | E16: ='Detail monthly summaryBD'!F170 -> 13102 | F16: =D16-G16 -> 4021 | G16: =E16 -> 13102 | H16: =E16/D16 -> 0.76516965
A17: 12 | B17: 11 | C17: Dessie | D17: ='Detail monthly summaryBD'!D50 -> 1447 | E17: ='Detail monthly summaryBD'!F50 -> 1085 | F17: =D17-G17 -> 362 | G17: =E17 -> 1085 | H17: =E17/D17 -> 0.74982723
A18: 13 | B18: 20 | C18: Jimma | D18: ='Detail monthly summaryBD'!D125 -> 711 | E18: ='Detail monthly summaryBD'!F125 -> 352 | F18: =D18-G18 -> 359 | G18: =E18 -> 352 | H18: =E18/D18 -> 0.49507736
B19: =SUM(B6:B18) -> 420 | C19: TOTAL | D19: =SUM(D6:D18) -> 123788 | E19: =SUM(E6:E18) -> 110220 | F19: =SUM(F6:F18) -> 13568 | G19: =SUM(G6:G18) -> 110220
F20: =F19/D19 -> 0.10960675 | G20: =G19/D19 -> 0.89039325
A21: NB: Out of the total 123,788 cases, only 110,220 cases have been rectified, representing 89% of the total cases. Accordingly, 11% of the cases remain unrectified.
I25: =I23-I24 -> 0

Sheet executive summary-edited
A1: SUMMARIZED IRREGULARITIES
A2: Covering from July,2025 up to August 24,2026
A3: 1.Monthly rectification on other cases
A4: SN | B4: Total No. of Branches | C4: District | D4: Others Case
F5: Rectified | G5: unrectified Balance | H5: Rectified percetage on total other cases | I5: previous week | J5: Difference
B6: A | C6: B | D6: Unrectified | E6: Rectified | F6: G | G6: H | H6: I
A7: 1 | B7: 36 | C7: Hossaena | D7: 8258 | E7: 8168 | F7: =D7-E7 -> 90 | G7: =E7 -> 8168 | H7: =E7/D7 -> 0.98910148 | I7: 0.97 | J7: =H7-I7 -> 0.019101477
A8: 2 | B8: 26 | C8: Wolkite | D8: 4666 | E8: 4550 | F8: =D8-E8 -> 116 | G8: =E8 -> 4550 | H8: =E8/D8 -> 0.97513931 | I8: 0.98 | J8: =H8-I8 -> -0.0048606944
A9: 3 | B9: 33 | C9: Adama | D9: 7287 | E9: 7077 | F9: =D9-E9 -> 210 | G9: =E9 -> 7077 | H9: =E9/D9 -> 0.97118156 | I9: 0.95 | J9: =H9-I9 -> 0.021181556
A10: 4 | B10: 49 | C10: East | D10: 11464 | E10: 10792 | F10: =D10-E10 -> 672 | G10: =E10 -> 10792 | H10: =E10/D10 -> 0.94138172 | I10: 0.9 | J10: =H10-I10 -> 0.041381717
A11: 5 | B11: 57 | C11: West | D11: 4823 | E11: 4467 | F11: =D11-E11 -> 356 | G11: =E11 -> 4467 | H11: =E11/D11 -> 0.92618702 | I11: 0.9 | J11: =H11-I11 -> 0.026187021
A12: 6 | B12: 7 | C12: Mekelle | D12: 564 | E12: 514 | F12: =D12-E12 -> 50 | G12: =E12 -> 514 | H12: =E12/D12 -> 0.91134752 | I12: 0.91 | J12: =H12-I12 -> 0.0013475177
A13: 7 | B13: 42 | C13: North | D13: 5042 | E13: 4583 | F13: =D13-E13 -> 459 | G13: =E13 -> 4583 | H13: =E13/D13 -> 0.9089647 | I13: 0.9 | J13: =H13-I13 -> 0.0089646965
A14: 8 | B14: 25 | C14: Bahi Dar | D14: 44363 | E14: 39917 | F14: =D14-E14 -> 4446 | G14: =E14 -> 39917 | H14: =E14/D14 -> 0.89978135 | I14: 0.89 | J14: =H14-I14 -> 0.0097813493
A15: 9 | B15: 39 | C15: Hawassa | D15: 12817 | E15: 11339 | F15: =D15-E15 -> 1478 | G15: =E15 -> 11339 | H15: =E15/D15 -> 0.8846844 | I15: 0.85 | J15: =H15-I15 -> 0.034684404
A16: 10 | B16: 17 | C16: DIREDAWA | D16: 5223 | E16: 4274 | F16: =D16-E16 -> 949 | G16: =E16 -> 4274 | H16: =E16/D16 -> 0.81830366 | I16: 0.83 | J16: =H16-I16 -> -0.011696343
A17: 11 | B17: 58 | C17: South | D17: 17123 | E17: 13102 | F17: =D17-E17 -> 4021 | G17: =E17 -> 13102 | H17: =E17/D17 -> 0.76516965 | I17: 0.72 | J17: =H17-I17 -> 0.045169655
A18: 12 | B18: 11 | C18: Dessie | D18: 1447 | E18: 1085 | F18: =D18-E18 -> 362 | G18: =E18 -> 1085 | H18: =E18/D18 -> 0.74982723 | I18: 0.72 | J18: =H18-I18 -> 0.029827229
A19: 13 | B19: 20 | C19: Jimma | D19: 711 | E19: 352 | F19: =D19-E19 -> 359 | G19: =E19 -> 352 | H19: =E19/D19 -> 0.49507736 | I19: 0.48 | J19: =H19-I19 -> 0.015077356
B20: =SUM(B7:B19) -> 420 | C20: TOTAL | D20: =SUM(D7:D19) -> 123788 | E20: =SUM(E7:E19) -> 110220 | F20: =SUM(F7:F19) -> 13568 | G20: =SUM(G7:G19) -> 110220
E21: =E20/D20 -> 0.89039325
A22: 2.Monthly rectification on ATM-related cases (mismatches and long-outstanding items)
A23: SN | B23: Total No. of Branches | C23: District | D23: ATM Cases | L23: Rectified percetage
D24: Mismatch | H24: Long outstanding
D25: Previous Balance as of July,2025 | E25: Rectified from July 2025 to March,2026 | F25: Additional from July 2025 to March,2026 | G25: Current unrectified Balance as of March,2026 | H25: Previous Balance as of July,2025 | I25: Rectified from July 2025 to March,2026 | J25: Additional from July 2025 to March,2026 | K25: Current unrectified Balance as of March,2026
B26: A | C26: B | D26: C | E26: D | F26: E | G26: F | H26: G | I26: H | J26: I | K26: J | L26: K
A27: 1 | B27: 20 | C27: Jimma | D27: ='[1]July 2025'!D17 -> 0 | E27: ='[1]July 2025'!E17+'[1]August,2025'!E17+'[1]Septeber,2025'!E17+'[1]October,2025'!E17+'[1]November,2025'!E17+'[1]December 2025'!E17+'[1]January,2026'!E16+'[1]February,2025'!E17+'[1]March,2026'!E17 -> 0 | F27: =G27+E27-D27 -> 129 | G27: 129 | H27: 68 | I27: ='[1]July 2025'!G17+'[1]August,2025'!G17+'[1]Septeber,2025'!G17+'[1]October,2025'!G17+'[1]November,2025'!G17+'[1]December 2025'!G17+'[1]January,2026'!G16+'[1]February,2025'!G17+'[1]March,2026'!G17 -> 280 | J27: =K27+I27-H27 -> 4326 | K27: 4114 | L27: =(E27+I27)/(D27+F27+H27+J27) -> 0.061905815
A28: 2 | B28: 49 | C28: East | D28: ='[1]July 2025'!D6 -> 359 | E28: 359 | F28: =G28+E28-D28 -> 0 | G28: 0 | H28: 0 | I28: ='[1]July 2025'!G6+'[1]August,2025'!G6+'[1]Septeber,2025'!G6+'[1]October,2025'!G6+'[1]November,2025'!G6+'[1]December 2025'!G6+'[1]January,2026'!G5+'[1]February,2025'!G6+'[1]March,2026'!G6 -> 51948 | J28: =K28+I28-H28 -> 76999 | K28: 25051 | L28: =(E28+I28)/(D28+F28+H28+J28) -> 0.67616795
A29: 3 | B29: 42 | C29: North | D29: ='[1]July 2025'!D7 -> 0 | E29: ='[1]July 2025'!E7+'[1]August,2025'!E7+'[1]Septeber,2025'!E7+'[1]October,2025'!E7+'[1]November,2025'!E7+'[1]December 2025'!E7+'[1]January,2026'!E6+'[1]February,2025'!E7+'[1]March,2026'!E7 -> 8582 | F29: =G29+E29-D29 -> 13775 | G29: 5193 | H29: 5573 | I29: ='[1]July 2025'!G7+'[1]August,2025'!G7+'[1]Septeber,2025'!G7+'[1]October,2025'!G7+'[1]November,2025'!G7+'[1]December 2025'!G7+'[1]January,2026'!G6+'[1]February,2025'!G7+'[1]March,2026'!G7 -> 3614 | J29: =K29+I29-H29 -> 14441 | K29: 16400 | L29: =(E29+I29)/(D29+F29+H29+J29) -> 0.36094587
A30: 4 | B30: 7 | C30: Mekelle | D30: ='[1]July 2025'!D18 -> 0 | E30: ='[1]July 2025'!E18+'[1]August,2025'!E18+'[1]Septeber,2025'!E18+'[1]October,2025'!E18+'[1]November,2025'!E18+'[1]December 2025'!E18+'[1]January,2026'!E17+'[1]February,2025'!E18+'[1]March,2026'!E18 -> 378 | F30: =G30+E30-D30 -> 378 | G30: 0 | H30: 0 | I30: ='[1]July 2025'!G18+'[1]August,2025'!G18+'[1]Septeber,2025'!G18+'[1]October,2025'!G18+'[1]November,2025'!G18+'[1]December 2025'!G18+'[1]January,2026'!G17+'[1]February,2025'!G18+'[1]March,2026'!G18 -> 290 | J30: =K30+I30-H30 -> 1824 | K30: 1534 | L30: =(E30+I30)/(D30+F30+H30+J30) -> 0.30336058
A31: 5 | B31: 11 | C31: Dessie | D31: ='[1]July 2025'!D12 -> 0 | E31: ='[1]July 2025'!E12+'[1]August,2025'!E12+'[1]Septeber,2025'!E12+'[1]October,2025'!E12+'[1]November,2025'!E12+'[1]December 2025'!E12+'[1]January,2026'!E11+'[1]February,2025'!E12+'[1]March,2026'!E12 -> 2 | F31: =G31+E31-D31 -> 1107 | G31: 1105 | H31: 767 | I31: ='[1]July 2025'!G12+'[1]August,2025'!G12+'[1]Septeber,2025'!G12+'[1]October,2025'!G12+'[1]November,2025'!G12+'[1]December 2025'!G12+'[1]January,2026'!G11+'[1]February,2025'!G12+'[1]March,2026'!G12 -> 927 | J31: =K31+I31-H31 -> 2800 | K31: 2640 | L31: =(E31+I31)/(D31+F31+H31+J31) -> 0.19875909
A32: 6 | B32: 17 | C32: DIREDAWA | D32: ='[1]July 2025'!D13 -> 209 | E32: ='[1]July 2025'!E13+'[1]August,2025'!E13+'[1]Septeber,2025'!E13+'[1]October,2025'!E13+'[1]November,2025'!E13+'[1]December 2025'!E13+'[1]January,2026'!E12+'[1]February,2025'!E13+'[1]March,2026'!E13 -> 306 | F32: =G32+E32-D32 -> 1463 | G32: 1366 | H32: 1084 | I32: ='[1]July 2025'!G13+'[1]August,2025'!G13+'[1]Septeber,2025'!G13+'[1]October,2025'!G13+'[1]November,2025'!G13+'[1]December 2025'!G13+'[1]January,2026'!G12+'[1]February,2025'!G13+'[1]March,2026'!G13 -> 2054 | J32: =K32+I32-H32 -> 9011 | K32: 8041 | L32: =(E32+I32)/(D32+F32+H32+J32) -> 0.20056089
A33: 7 | B33: 25 | C33: Bahi Dar | D33: ='[1]July 2025'!D11 -> 0 | E33: ='[1]July 2025'!E11+'[1]August,2025'!E11+'[1]Septeber,2025'!E11+'[1]October,2025'!E11+'[1]November,2025'!E11+'[1]December 2025'!E11+'[1]January,2026'!E10+'[1]February,2025'!E11+'[1]March,2026'!E11 -> 947 | F33: =G33+E33-D33 -> 2500 | G33: 1553 | H33: 1373 | I33: ='[1]July 2025'!G11+'[1]August,2025'!G11+'[1]Septeber,2025'!G11+'[1]October,2025'!G11+'[1]November,2025'!G11+'[1]December 2025'!G11+'[1]January,2026'!G10+'[1]February,2025'!G11+'[1]March,2026'!G11 -> 1455 | J33: =K33+I33-H33 -> 8917 | K33: 8835 | L33: =(E33+I33)/(D33+F33+H33+J33) -> 0.18780297
A34: 8 | B34: 26 | C34: Wolkite | D34: ='[1]July 2025'!D16 -> 701 | E34: ='[1]July 2025'!E16+'[1]August,2025'!E16+'[1]Septeber,2025'!E16+'[1]October,2025'!E16+'[1]November,2025'!E16+'[1]December 2025'!E16+'[1]January,2026'!E15+'[1]February,2025'!E16+'[1]March,2026'!E16 -> 1048 | F34: =G34+E34-D34 -> 569 | G34: 222 | H34: 726 | I34: ='[1]July 2025'!G16+'[1]August,2025'!G16+'[1]Septeber,2025'!G16+'[1]October,2025'!G16+'[1]November,2025'!G16+'[1]December 2025'!G16+'[1]January,2026'!G15+'[1]February,2025'!G16+'[1]March,2026'!G16 -> 2160 | J34: =K34+I34-H34 -> 17859 | K34: 16425 | L34: =(E34+I34)/(D34+F34+H34+J34) -> 0.16157139
A35: 9 | B35: 36 | C35: Hossaena | D35: ='[1]July 2025'!D15 -> 0 | E35: ='[1]July 2025'!E15+'[1]August,2025'!E15+'[1]Septeber,2025'!E15+'[1]October,2025'!E15+'[1]November,2025'!E15+'[1]December 2025'!E15+'[1]January,2026'!E14+'[1]February,2025'!E15+'[1]March,2026'!E15 -> 377 | F35: =G35+E35-D35 -> 6337 | G35: 5960 | H35: 4994 | I35: ='[1]July 2025'!G15+'[1]August,2025'!G15+'[1]Septeber,2025'!G15+'[1]October,2025'!G15+'[1]November,2025'!G15+'[1]December 2025'!G15+'[1]January,2026'!G14+'[1]February,2025'!G15+'[1]March,2026'!G15 -> 7051 | J35: =K35+I35-H35 -> 49692 | K35: 47635 | L35: =(E35+I35)/(D35+F35+H35+J35) -> 0.1217246
A36: 10 | B36: 33 | C36: Adama | D36: ='[1]July 2025'!D10 -> 784 | E36: ='[1]July 2025'!E10+'[1]August,2025'!E10+'[1]Septeber,2025'!E10+'[1]October,2025'!E10+'[1]November,2025'!E10+'[1]December 2025'!E10+'[1]January,2026'!E9+'[1]February,2025'!E10+'[1]March,2026'!E10 -> 9 | F36: =G36+E36-D36 -> 437 | G36: 1212 | H36: 1337 | I36: ='[1]July 2025'!G10+'[1]August,2025'!G10+'[1]Septeber,2025'!G10+'[1]October,2025'!G10+'[1]November,2025'!G10+'[1]December 2025'!G10+'[1]January,2026'!G9+'[1]February,2025'!G10+'[1]March,2026'!G10 -> 739 | J36: =K36+I36-H36 -> 15968 | K36: 16566 | L36: =(E36+I36)/(D36+F36+H36+J36) -> 0.040375688
B37: 52 | C37: South | D37: ='[1]July 2025'!D8 -> 150 | E37: ='[1]July 2025'!E8+'[1]August,2025'!E8+'[1]Septeber,2025'!E8+'[1]October,2025'!E8+'[1]November,2025'!E8+'[1]December 2025'!E8+'[1]January,2026'!E7+'[1]February,2025'!E8+'[1]March,2026'!E8 -> 48 | F37: =G37+E37-D37 -> 7916 | G37: 8018 | H37: 7486 | I37: ='[1]July 2025'!G8+'[1]August,2025'!G8+'[1]Septeber,2025'!G8+'[1]October,2025'!G8+'[1]November,2025'!G8+'[1]December 2025'!G8+'[1]January,2026'!G7+'[1]February,2025'!G8+'[1]March,2026'!G8 -> 180 | J37: =K37+I37-H37 -> 20198 | K37: 27504 | L37: =(E37+I37)/(D37+F37+H37+J37) -> 0.0063776224
A38: 11 | B38: 39 | C38: Hawassa | D38: ='[1]July 2025'!D14 -> 0 | E38: ='[1]July 2025'!E14+'[1]August,2025'!E14+'[1]Septeber,2025'!E14+'[1]October,2025'!E14+'[1]November,2025'!E14+'[1]December 2025'!E14+'[1]January,2026'!E13+'[1]February,2025'!E14+'[1]March,2026'!E14 -> 109 | F38: =G38+E38-D38 -> 3429 | G38: 3320 | H38: 2335 | I38: ='[1]July 2025'!G14+'[1]August,2025'!G14+'[1]Septeber,2025'!G14+'[1]October,2025'!G14+'[1]November,2025'!G14+'[1]December 2025'!G14+'[1]January,2026'!G13+'[1]February,2025'!G14+'[1]March,2026'!G14 -> 36 | J38: =K38+I38-H38 -> 27569 | K38: 29868 | L38: =(E38+I38)/(D38+F38+H38+J38) -> 0.0043500435
A39: 12 | B39: 65 | C39: West | D39: ='[1]July 2025'!D9 -> 779 | E39: ='[1]July 2025'!E9+'[1]August,2025'!E9+'[1]Septeber,2025'!E9+'[1]October,2025'!E9+'[1]November,2025'!E9+'[1]December 2025'!E9+'[1]January,2026'!E8+'[1]February,2025'!E9+'[1]March,2026'!E9 -> 3 | F39: =G39+E39-D39 -> 5000 | G39: 5776 | H39: 5471 | I39: ='[1]July 2025'!G9+'[1]August,2025'!G9+'[1]Septeber,2025'!G9+'[1]October,2025'!G9+'[1]November,2025'!G9+'[1]December 2025'!G9+'[1]January,2026'!G8+'[1]February,2025'!G9+'[1]March,2026'!G9 -> 0 | J39: =K39+I39-H39 -> 14438 | K39: 19909 | L39: =(E39+I39)/(D39+F39+H39+J39) -> 0.00011678605
B40: =SUM(B27:B39) -> 422 | C40: TOTAL | D40: =SUM(D27:D39) -> 2982 | E40: =SUM(E27:E39) -> 12168 | F40: =SUM(F27:F39) -> 43040 | G40: =SUM(G27:G39) -> 33854 | H40: =SUM(H27:H39) -> 31214 | I40: =SUM(I27:I39) -> 70734 | J40: =SUM(J27:J39) -> 264042 | K40: =SUM(K27:K39) -> 224522 | L40: =(E40+I40)/(D40+F40+H40+J40) -> 0.24291633 | M40: =D40+F40+H40+J40 -> 341278 | N40: =E40+I40 -> 82902 | O40: =N40/M40 -> 0.24291633
...

Sheet Ranks in all cases
A1: EXECUTIVE SUMMARIZED IRREGULARITIES
A2: Covering from July,2025 up to August 24,2026
A3: PERFORMANCE REPORT ON RECTIFICATION OF THE ENTIRE IRREGULARITIES
A4: SN | B4: Total No. of Branches | C4: District | D4: Total Cases | F4: Status of the irregularities
F5: Total outstanding unrectified cases | G5: Rectified | H5: Rank in all cases
B6: A | C6: B | D6: Unrectified | E6: Rectified | F6: F | G6: G | H6: I
A7: 1 | B7: 25 | C7: Bahi Dar | D7: ='executive summary-edited'!D13+'executive summary-edited'!D33+'executive summary-edited'!F33+'executive summary-edited'!H33+'executive summary-edited'!J33+'executive summary-edited'!D58+'executive summary-edited'!F58+'executive summary-edited'!D75+'executive summary-edited'!F75+'executive summary-edited'!D88+'executive summary-edited'!F88+'executive summary-edited'!D116+'executive summary-edited'!F116 -> 138027 | E7: ='executive summary-edited'!E13+'executive summary-edited'!E33+'executive summary-edited'!I33+'executive summary-edited'!E58+'executive summary-edited'!E75+'executive summary-edited'!E88+'executive summary-edited'!E116 -> 102378 | F7: =D7-E7 -> 35649 | G7: =E7 -> 102378 | H7: =E7/D7 -> 0.74172445
A8: 2 | B8: 49 | C8: East | D8: ='executive summary-edited'!D14+'executive summary-edited'!D28+'executive summary-edited'!F28+'executive summary-edited'!H28+'executive summary-edited'!J28+'executive summary-edited'!D51+'executive summary-edited'!F51+'executive summary-edited'!D73+'executive summary-edited'!F73+'executive summary-edited'!D91+'executive summary-edited'!F91+'executive summary-edited'!D110+'executive summary-edited'!F110 -> 445291 | E8: ='executive summary-edited'!E14+'executive summary-edited'!E28+'executive summary-edited'!I28+'executive summary-edited'!E51+'executive summary-edited'!E73+'executive summary-edited'!E91+'executive summary-edited'!E110 -> 323846 | F8: =D8-E8 -> 121445 | G8: =E8 -> 323846 | H8: =E8/D8 -> 0.72726824
A9: 3 | B9: 7 | C9: Mekelle | D9: ='executive summary-edited'!D12+'executive summary-edited'!D30+'executive summary-edited'!F30+'executive summary-edited'!H30+'executive summary-edited'!J30+'executive summary-edited'!D52+'executive summary-edited'!F52+'executive summary-edited'!D67+'executive summary-edited'!F67+'executive summary-edited'!D95+'executive summary-edited'!F95+'executive summary-edited'!D112+'executive summary-edited'!F112 -> 19848 | E9: ='executive summary-edited'!E12+'executive summary-edited'!E30+'executive summary-edited'!I30+'executive summary-edited'!E52+'executive summary-edited'!E67+'executive summary-edited'!E95+'executive summary-edited'!E112 -> 11981 | F9: =D9-E9 -> 7867 | G9: =E9 -> 11981 | H9: =E9/D9 -> 0.60363765
A10: 4 | B10: 11 | C10: Dessie | D10: ='executive summary-edited'!D15+'executive summary-edited'!D31+'executive summary-edited'!F31+'executive summary-edited'!H31+'executive summary-edited'!J31+'executive summary-edited'!D60+'executive summary-edited'!F60+'executive summary-edited'!D78+'executive summary-edited'!F78+'executive summary-edited'!D89+'executive summary-edited'!F89+'executive summary-edited'!D117+'executive summary-edited'!F117 -> 76076 | E10: ='executive summary-edited'!E15+'executive summary-edited'!E31+'executive summary-edited'!I31+'executive summary-edited'!E60+'executive summary-edited'!E78+'executive summary-edited'!E89+'executive summary-edited'!E117 -> 53870 | F10: =D10-E10 -> 22206 | G10: =E10 -> 53870 | H10: =E10/D10 -> 0.70810768
A11: 5 | B11: 39 | C11: Hawassa | D11: ='executive summary-edited'!D16+'executive summary-edited'!D38+'executive summary-edited'!F38+'executive summary-edited'!H38+'executive summary-edited'!J38+'executive summary-edited'!D56+'executive summary-edited'!F56+'executive summary-edited'!D69+'executive summary-edited'!F69+'executive summary-edited'!D87+'executive summary-edited'!F87+'executive summary-edited'!D107+'executive summary-edited'!F107 -> 125016 | E11: ='executive summary-edited'!E16+'executive summary-edited'!E38+'executive summary-edited'!I38+'executive summary-edited'!E56+'executive summary-edited'!E69+'executive summary-edited'!E87+'executive summary-edited'!E107 -> 72168 | F11: =D11-E11 -> 52848 | G11: =E11 -> 72168 | H11: =E11/D11 -> 0.57727011
A12: 6 | B12: 42 | C12: North | D12: ='executive summary-edited'!D10+'executive summary-edited'!D29+'executive summary-edited'!F29+'executive summary-edited'!H29+'executive summary-edited'!J29+'executive summary-edited'!D57+'executive summary-edited'!F57+'executive summary-edited'!D76+'executive summary-edited'!F76+'executive summary-edited'!D90+'executive summary-edited'!F90+'executive summary-edited'!D113+'executive summary-edited'!F113 -> 142572 | E12: ='executive summary-edited'!E10+'executive summary-edited'!E29+'executive summary-edited'!I29+'executive summary-edited'!E57+'executive summary-edited'!E76+'executive summary-edited'!E90+'executive summary-edited'!E113 -> 83502 | F12: =D12-E12 -> 59070 | G12: =E12 -> 83502 | H12: =E12/D12 -> 0.58568302
A13: 7 | B13: 17 | C13: DIREDAWA | D13: ='executive summary-edited'!D11+'executive summary-edited'!D32+'executive summary-edited'!F32+'executive summary-edited'!H32+'executive summary-edited'!J32+'executive summary-edited'!D49+'executive summary-edited'!F49+'executive summary-edited'!D74+'executive summary-edited'!F74+'executive summary-edited'!D92+'executive summary-edited'!F92+'executive summary-edited'!D105+'executive summary-edited'!F105 -> 72929 | E13: ='executive summary-edited'!E11+'executive summary-edited'!E32+'executive summary-edited'!I32+'executive summary-edited'!E49+'executive summary-edited'!E74+'executive summary-edited'!E92+'executive summary-edited'!E105 -> 37987 | F13: =D13-E13 -> 34942 | G13: =E13 -> 37987 | H13: =E13/D13 -> 0.52087647
A14: 8 | B14: 26 | C14: Wolkite | D14: ='executive summary-edited'!D9+'executive summary-edited'!D34+'executive summary-edited'!F34+'executive summary-edited'!H34+'executive summary-edited'!J34+'executive summary-edited'!D50+'executive summary-edited'!F50+'executive summary-edited'!D77+'executive summary-edited'!F77+'executive summary-edited'!D94+'executive summary-edited'!F94+'executive summary-edited'!D106+'executive summary-edited'!F106 -> 134909 | E14: ='executive summary-edited'!E9+'executive summary-edited'!E34+'executive summary-edited'!I34+'executive summary-edited'!E50+'executive summary-edited'!E77+'executive summary-edited'!E94+'executive summary-edited'!E106 -> 64024 | F14: =D14-E14 -> 70885 | G14: =E14 -> 64024 | H14: =E14/D14 -> 0.47457175
A15: 9 | B15: 36 | C15: Hossaena | D15: ='executive summary-edited'!D7+'executive summary-edited'!D35+'executive summary-edited'!F35+'executive summary-edited'!H35+'executive summary-edited'!J35+'executive summary-edited'!D55+'executive summary-edited'!F55+'executive summary-edited'!D70+'executive summary-edited'!F70+'executive summary-edited'!D93+'executive summary-edited'!F93+'executive summary-edited'!D111+'executive summary-edited'!F111 -> 329121 | E15: ='executive summary-edited'!E7+'executive summary-edited'!E35+'executive summary-edited'!I35+'executive summary-edited'!E55+'executive summary-edited'!E70+'executive summary-edited'!E93+'executive summary-edited'!E111 -> 155128 | F15: =D15-E15 -> 173993 | G15: =E15 -> 155128 | H15: =E15/D15 -> 0.47134033
A16: 10 | B16: 33 | C16: Adama | D16: ='executive summary-edited'!D8+'executive summary-edited'!D36+'executive summary-edited'!F36+'executive summary-edited'!H36+'executive summary-edited'!J36+'executive summary-edited'!D54+'executive summary-edited'!F54+'executive summary-edited'!D72+'executive summary-edited'!F72+'executive summary-edited'!D97+'executive summary-edited'!F97+'executive summary-edited'!D109+'executive summary-edited'!F109 -> 157545 | E16: ='executive summary-edited'!E8+'executive summary-edited'!E36+'executive summary-edited'!I36+'executive summary-edited'!E54+'executive summary-edited'!E72+'executive summary-edited'!E97+'executive summary-edited'!E109 -> 44591 | F16: =D16-E16 -> 112954 | G16: =E16 -> 44591 | H16: =E16/D16 -> 0.28303659
A17: 11 | B17: 57 | C17: West | D17: ='executive summary-edited'!D19+'executive summary-edited'!D39+'executive summary-edited'!F39+'executive summary-edited'!H39+'executive summary-edited'!J39+'executive summary-edited'!D59+'executive summary-edited'!F59+'executive summary-edited'!D71+'executive summary-edited'!F71+'executive summary-edited'!D96+'executive summary-edited'!F96+'executive summary-edited'!D115+'executive summary-edited'!F115 -> 164564 | E17: ='executive summary-edited'!E18+'executive summary-edited'!E39+'executive summary-edited'!I39+'executive summary-edited'!E59+'executive summary-edited'!E71+'executive summary-edited'!E96+'executive summary-edited'!E115 -> 44146 | F17: =D17-E17 -> 120418 | G17: =E17 -> 44146 | H17: =E17/D17 -> 0.26826037
A18: 12 | B18: 20 | C18: Jimma | D18: ='executive summary-edited'!D17+'executive summary-edited'!D27+'executive summary-edited'!F27+'executive summary-edited'!H27+'executive summary-edited'!J27+'executive summary-edited'!D48+'executive summary-edited'!F48+'executive summary-edited'!D68+'executive summary-edited'!F68+'executive summary-edited'!D86+'executive summary-edited'!F86+'executive summary-edited'!D108+'executive summary-edited'!F108 -> 92997 | E18: ='executive summary-edited'!E17+'executive summary-edited'!E27+'executive summary-edited'!I27+'executive summary-edited'!E48+'executive summary-edited'!E68+'executive summary-edited'!E86+'executive summary-edited'!E108 -> 19183 | F18: =D18-E18 -> 73814 | G18: =E18 -> 19183 | H18: =E18/D18 -> 0.20627547
A19: 13 | B19: 58 | C19: South | D19: ='executive summary-edited'!D18+'executive summary-edited'!D37+'executive summary-edited'!F37+'executive summary-edited'!H37+'executive summary-edited'!J37+'executive summary-edited'!D53+'executive summary-edited'!F53+'executive summary-edited'!D79+'executive summary-edited'!F79+'executive summary-edited'!D98+'executive summary-edited'!F98+'executive summary-edited'!D114+'executive summary-edited'!F114 -> 230007 | E19: ='executive summary-edited'!E18+'executive summary-edited'!E37+'executive summary-edited'!I37+'executive summary-edited'!E53+'executive summary-edited'!E79+'executive summary-edited'!E98+'executive summary-edited'!E114 -> 24524 | F19: =D19-E19 -> 205483 | G19: =E19 -> 24524 | H19: =E19/D19 -> 0.10662284
B20: =SUM(B7:B19) -> 420 | C20: TOTAL | D20: =SUM(D7:D19) -> 2128902 | E20: =SUM(E7:E19) -> 1037328 | F20: =SUM(F7:F19) -> 1091574 | G20: =SUM(G7:G19) -> 1037328
F21: =F20/D20 -> 0.51274037 | G21: =G20/D20 -> 0.48725963
E22: ='executive summary-edited'!E20+'executive summary-edited'!E40+'executive summary-edited'!I40+'executive summary-edited'!E61+'executive summary-edited'!E80+'executive summary-edited'!E99+'executive summary-edited'!E118 -> 1036595
D23: 2128902 | E23: 1036595
D24: =D20-D23 -> 0 | E24: =E20-E23 -> 733

Sheet Gross percentages
A2: PERFORMANCE REPORT ON RECTIFICATION OF THE ENTIRE IRREGULARITIES
A3: Range of percentage & Gross Percentage as of August 24,2026
A4: SN | B4: Types of cases | C4: Unrectified | D4: Rectified | E4: Total outstanding unrectified cases | F4: Percentage ranges | G4: Gross percentage | H4: Previous week
A6: 1 | B6: Other cases | C6: 123788 | D6: 110220 | E6: =C6-D6 -> 13568 | F6: 50% up to 99% | G6: 0.89 | H6: 0.88
A7: 2 | B7: ATM-related cases (mismatches and long-outstanding items) | C7: 341278 | D7: 82902 | E7: =C7-D7 -> 258376 | F7: 0% up to 68% | G7: 0.24 | H7: 0.25
A8: 3 | B8: IT-related issues/cases | C8: 6040 | D8: 4947 | E8: =C8-D8 -> 1093 | F8: 9% up to 100% | G8: 0.82 | H8: 0.83
A9: 4 | B9: Number of zero-balance | C9: 111742 | D9: 81864 | E9: =C9-D9 -> 29878 | F9: 1% up to 100% | G9: 0.73 | H9: 0.76
A10: 5 | B10: Number of inactive accounts | C10: 1535191 | D10: 753135 | E10: =C10-D10 -> 782056 | F10: 8% up to 80% | G10: 0.49 | H10: 0.54
A11: 6 | B11: cheques not delivered to customers | C11: 10863 | D11: 3527 | E11: =C11-D11 -> 7336 | F11: 14% up to 100% | G11: 0.32 | H11: 0.31
B12: TOTAL | C12: =SUM(C6:C11) -> 2128902 | D12: =SUM(D6:D11) -> 1036595 | E12: =C12-D12 -> 1092307 | F12: =SUM(F6:F11) -> 0 | G12: =D12/C12 -> 0.48691532
D13: =D12/C12 -> 0.48691532

Sheet Sheet1
A2: ENTIRE SUMMARIZED IRREGULARITIES AS AT JULY 13,2026
A3: SN | B3: District | D3: Others Cases | E3: Status of the irregularities
C4: Month | E4: Unrectified | F4: Rectified | G4: rectified percetage
B5: A | C5: B | D5: C | E5: D | F5: F | G5: G
A6: 1 | B6: Hossaena | C6: 46204 | D6: 234 | E6: =D6-F6 -> 28 | F6: 206 | G6: =F6/D6 -> 0.88034188
A7: 2 | B7: Mekelle | C7: 46204 | D7: 6 | E7: =D7-F7 -> 3 | F7: 3 | G7: =F7/D7 -> 0.5
A8: 3 | B8: East | C8: 46204 | D8: 625 | E8: =D8-F8 -> 384 | F8: 241 | G8: =F8/D8 -> 0.3856
A9: 4 | B9: North | C9: 46204 | D9: 228 | E9: =D9-F9 -> 163 | F9: 65 | G9: =F9/D9 -> 0.28508772
A10: 5 | B10: Dessie | C10: 46204 | D10: 268 | E10: =D10-F10 -> 219 | F10: 49 | G10: =F10/D10 -> 0.18283582
A11: 6 | B11: West | C11: 46204 | D11: 160 | E11: =D11-F11 -> 140 | F11: 20 | G11: =F11/D11 -> 0.125
A12: 7 | B12: Wolkite | C12: 46204 | D12: 101 | E12: =D12-F12 -> 90 | F12: 11 | G12: =F12/D12 -> 0.10891089
A13: 8 | B13: Adama | C13: 46204 | D13: 207 | E13: =D13-F13 -> 187 | F13: 20 | G13: =F13/D13 -> 0.096618357
A14: 9 | B14: Bahi Dar | C14: 46204 | D14: 4342 | E14: =D14-F14 -> 4090 | F14: 252 | G14: =F14/D14 -> 0.058037771
A15: 10 | B15: South | C15: 46204 | D15: 818 | E15: =D15-F15 -> 810 | F15: 8 | G15: =F15/D15 -> 0.0097799511
A16: 11 | B16: DIREDAWA | C16: 46204 | D16: 240 | E16: =D16-F16 -> 240 | F16: 0 | G16: =F16/D16 -> 0
A17: 12 | B17: Hawassa | C17: 46204 | D17: 582 | E17: =D17-F17 -> 582 | F17: 0 | G17: =F17/D17 -> 0
A18: 13 | B18: Jimma | C18: 46204 | D18: 300 | E18: =D18-F18 -> 300 | F18: 0 | G18: =F18/D18 -> 0
B19: TOTAL | D19: =SUM(D6:D18) -> 8111 | E19: =SUM(E6:E18) -> 7236 | F19: =SUM(F6:F18) -> 875 | G19: =F19/D19 -> 0.10787819
F20: =F19/D19 -> 0.10787819
